Workbook

Sheet Сводная
A1: Наим. | B1: Стенка H | C1: Полка B1 | D1: Полка B2 | F1: Сечение профиля, | H1: Толщина металла, мм | I1: Геометрические характеристики полного поперечного сечения | T1: Масса 1 м.п. | U1: Теор. Ширина заготовки, мм | V1: момент инерции при свободном кручении для одиночного профиля | W1: момент инерции при свободном кручении для сдвоенного профиля | X1: Момент инерции Jy сдвоенного сечения (SCAD-Tonus)
F2: Тип | G2: Н/В1/В2, мм | I2: Площадь сечения | J2: Момент инерции | K2: Момент сопро- | L2: Момент инерции | M2: Момент сопр-я | N2: радиус инерции | P2: Положение центра тяжести
I4: Fp, | J4: Jx, | K4: Wx, | L4: Jy, | M4: Wy, | N4: rx, | O4: ry, | P4: x0, | Q4: x1, | R4: y0, | S4: y1,
I5: см2 | J5: см4 | K5: см3 | L5: см4 | M5: см3 | N5: см | O5: см | P5: см | Q5: см | R5: см | S5: см
A6: Z140x1,5 | B6: =Z!B2 -> 140 | C6: =Z!C2 -> 59.5 | D6: =Z!D2 -> 65.5 | E6: =Z!E2 -> 20 | F6: =Z!F2 -> Z140 | G6: =Z!G2 -> 140/59,5/65,5/20 | H6: =Z!H2 -> 1.5 | I6: =Z!I2 -> 4.37 | ... T6: =Z!T2 -> 3.42 | V6: =Z!V2 -> 0.0327 | W6: =Z!W2 -> 0.0654 | X6: =Z!X2 -> 406.5397
A7: ZR300x3,5 | B7: =ZR!B2 -> 300 | C7: =ZR!C2 -> 88 | D7: =ZR!D2 -> 96 | E7: =ZR!E2 -> 23.5 | F7: =ZR!F2 -> ZR300 | G7: =ZR!G2 -> 300/88/96/23,5 | H7: =ZR!H2 -> 3.5 | I7: =ZR!I2 -> 18.24 | ... T7: =ZR!T2 -> 14.41 | V7: =ZR!V2 -> 0.7478 | W7: =ZR!W2 -> 1.4956 | X7: =ZR!X2 -> 3871.9645
A8: SIGMA350x3,5 | B8: =S!B2 -> 350 | C8: =S!C2 -> 100 | D8: =S!D2 -> 100 | E8: =S!E2 -> 26 | F8: =S!F2 -> SIGMA350 | G8: =S!G2 -> 350/100/100/26 | H8: =S!H2 -> 3.5 | I8: =S!I2 -> 20.73 | ... T8: =S!T2 -> 16.26 | V8: =S!V2 -> 0.849 | W8: =S!W2 -> 1.699 | X8: =S!X2 -> 820.996
A9: C250x2,5 | B9: ='C'!B2 -> 250 | C9: ='C'!C2 -> 72 | D9: ='C'!D2 -> 72 | E9: ='C'!E2 -> 22 | F9: ='C'!F2 -> C250 | G9: ='C'!G2 -> 250/72/72/22 | H9: ='C'!H2 -> 2.5 | I9: ='C'!I2 -> 10.47 | ... T9: ='C'!T2 -> 8.22 | V9: ='C'!V2 -> 0.218 | W9: ='C'!W2 -> 0.436 | X9: ='C'!X2 -> 235.721
A11: Наим. | B11: Стенка H | C11: Полка B1 | D11: Полка B2 | E11: Отгибы С | F11: Сечение профиля, | H11: Толщина металла, мм | I11: Масса 1 п.м. | J11: Расчетные справочные величины для профилей при продольном сжатии | L11: Расчетные справочные величины при изгибе | AA11: Предел текучести
L12: В плоскости х - х | V12: В плоскости у - у
L13: Сжата полка В1 | Q13: Сжата полка В2
F14: Тип | G14: Н/В1/В2, мм | J14: Площадь сечения | K14: Радиус инерции | L14: Площадь сечения | M14: Момент инерции | N14: Момент инерции | O14: Радиус инерции | P14: Полож-е ц/т | Q14: Площадь сечения | R14: Момент инерции | S14: Момент сопр-я | T14: Радиус инерции | U14: Полож-е ц/т | V14: Площадь сечения | W14: Мом-ент инерции | X14: Момент сопр-я | Y14: Радиус инерции | Z14: Полож-е ц/т
J16: Fp, | K16: rmin, | L16: Fp, | M16: Jx, | N16: Wx, | O16: rx, | P16: y0, | Q16: Fp, | R16: Jx, | S16: Wx, | T16: rx, | U16: y0, | V16: Fp, | W16: Jy, | X16: Wy, | Y16: ry, | Z16: x0, | AA16: Ry
I17: кг | J17: см2 | K17: см | L17: см2 | M17: см4 | N17: см3 | O17: см | P17: см | Q17: см2 | R17: см4 | S17: см3 | T17: см | U17: см | V17: см2 | W17: см4 | X17: см3 | Y17: см | Z17: см | AA17: кг/см4
A18: Z250x2,5 | B18: =Z_R_280!B2 -> 250 | C18: =Z_R_280!C2 -> 68 | D18: =Z_R_280!D2 -> 79 | E18: =Z_R_280!E2 -> 22 | F18: =Z_R_280!F2 -> Z250 | G18: =Z_R_280!G2 -> 250/68/79/22 | H18: =Z_R_280!H2 -> 2.5 | I18: =Z_R_280!I2 -> 8.28 | ... Z18: =Z_R_280!Z2 -> 6.91 | AA18: C280
A19: =A18 -> Z250x2,5 | B19: =Z_R_350!B2 -> 250 | C19: =Z_R_350!C2 -> 68 | D19: =Z_R_350!D2 -> 79 | E19: =Z_R_350!E2 -> 22 | F19: =Z_R_350!F2 -> Z250 | G19: =Z_R_350!G2 -> 250/68/79/22 | H19: =Z_R_350!H2 -> 2.5 | I19: =Z_R_350!I2 -> 8.28 | ... Z19: =Z_R_350!Z2 -> 6.91 | AA19: С350
A20: =A18 -> Z250x2,5 | B20: =Z_R_390!B2 -> 250 | C20: =Z_R_390!C2 -> 68 | D20: =Z_R_390!D2 -> 79 | E20: =Z_R_390!E2 -> 22 | F20: =Z_R_390!F2 -> Z250 | G20: =Z_R_390!G2 -> 250/68/79/22 | H20: =Z_R_390!H2 -> 2.5 | I20: =Z_R_390!I2 -> 8.28 | ... Z20: =Z_R_390!Z2 -> 6.91 | AA20: С390
A21: =A18 -> Z250x2,5 | B21: =Z_R_420!B2 -> 250 | C21: =Z_R_420!C2 -> 68 | D21: =Z_R_420!D2 -> 79 | E21: =Z_R_420!E2 -> 22 | F21: =Z_R_420!F2 -> Z250 | G21: =Z_R_420!G2 -> 250/68/79/22 | H21: =Z_R_420!H2 -> 2.5 | I21: =Z_R_420!I2 -> 8.28 | ... Z21: =Z_R_420!Z2 -> 6.91 | AA21: С420
A22: =A18 -> Z250x2,5 | B22: =Z_R_450!B2 -> 250 | C22: =Z_R_450!C2 -> 68 | D22: =Z_R_450!D2 -> 79 | E22: =Z_R_450!E2 -> 22 | F22: =Z_R_450!F2 -> Z250 | G22: =Z_R_450!G2 -> 250/68/79/22 | H22: =Z_R_450!H2 -> 2.5 | I22: =Z_R_450!I2 -> 8.28 | ... Z22: =Z_R_450!Z2 -> 6.91 | AA22: С450
A23: ZR250x2,0 | B23: =ZR_R_350!B2 -> 250 | C23: =ZR_R_350!C2 -> 63 | D23: =ZR_R_350!D2 -> 73 | E23: =ZR_R_350!E2 -> 20 | F23: =ZR_R_350!F2 -> ZR250 | G23: =ZR_R_350!G2 -> 250/63/73/20 | H23: =ZR_R_350!H2 -> 2 | I23: =ZR_R_350!I2 -> 6.68 | ... Z23: =ZR_R_350!Z2 -> 6.13 | AA23: С350
A24: =A23 -> ZR250x2,0 | B24: =ZR_R_390!B2 -> 250 | C24: =ZR_R_390!C2 -> 63 | D24: =ZR_R_390!D2 -> 73 | E24: =ZR_R_390!E2 -> 20 | F24: =ZR_R_390!F2 -> ZR250 | G24: =ZR_R_390!G2 -> 250/63/73/20 | H24: =ZR_R_390!H2 -> 2 | I24: =ZR_R_390!I2 -> 6.68 | ... Z24: =ZR_R_390!Z2 -> 6.13 | AA24: С390
A25: =A23 -> ZR250x2,0 | B25: =ZR_R_420!B2 -> 250 | C25: =ZR_R_420!C2 -> 63 | D25: =ZR_R_420!D2 -> 73 | E25: =ZR_R_420!E2 -> 20 | F25: =ZR_R_420!F2 -> ZR250 | G25: =ZR_R_420!G2 -> 250/63/73/20 | H25: =ZR_R_420!H2 -> 2 | I25: =ZR_R_420!I2 -> 6.68 | ... Z25: =ZR_R_420!Z2 -> 6.13 | AA25: С420
A26: SIGMA350x3,5 | B26: =S_R_350!B2 -> 350 | C26: =S_R_350!C2 -> 100 | D26: =S_R_350!D2 -> 100 | E26: =S_R_350!E2 -> 26 | F26: =S_R_350!F2 -> SIGMA350 | G26: =S_R_350!G2 -> 350/100/100/26 | H26: =S_R_350!H2 -> 3.5 | I26: =S_R_350!I2 -> 16.26 | ... Z26: =S_R_350!Z2 -> 2.8 | AA26: С350
A27: =A26 -> SIGMA350x3,5 | B27: =S_R_390!B2 -> 350 | C27: =S_R_390!C2 -> 100 | D27: =S_R_390!D2 -> 100 | E27: =S_R_390!E2 -> 26 | F27: =S_R_390!F2 -> SIGMA350 | G27: =S_R_390!G2 -> 350/100/100/26 | H27: =S_R_390!H2 -> 3.5 | I27: =S_R_390!I2 -> 16.26 | ... Z27: =S_R_390!Z2 -> 2.84 | AA27: С390
A28: =A26 -> SIGMA350x3,5 | B28: =S_R_420!B2 -> 350 | C28: =S_R_420!C2 -> 100 | D28: =S_R_420!D2 -> 100 | E28: =S_R_420!E2 -> 26 | F28: =S_R_420!F2 -> SIGMA350 | G28: =S_R_420!G2 -> 350/100/100/26 | H28: =S_R_420!H2 -> 3.5 | I28: =S_R_420!I2 -> 16.26 | ... Z28: =S_R_420!Z2 -> 2.87 | AA28: С420
A29: C170x2,0 | B29: =C_R_350!B2 -> 170 | C29: =C_R_350!C2 -> 68 | D29: =C_R_350!D2 -> 68 | E29: =C_R_350!E2 -> 17 | F29: =C_R_350!F2 -> C170 | G29: =C_R_350!G2 -> 170/68/68/17 | H29: =C_R_350!H2 -> 2 | I29: =C_R_350!I2 -> 5.08 | ... Z29: =C_R_350!Z2 -> 2.68 | AA29: С350
A30: =A29 -> C170x2,0 | B30: =C_R_390!B2 -> 170 | C30: =C_R_390!C2 -> 68 | D30: =C_R_390!D2 -> 68 | E30: =C_R_390!E2 -> 17 | F30: =C_R_390!F2 -> C170 | G30: =C_R_390!G2 -> 170/68/68/17 | H30: =C_R_390!H2 -> 2 | I30: =C_R_390!I2 -> 5.08 | ... Z30: =C_R_390!Z2 -> 2.72 | AA30: С390
B33: Авп | C33: 18.28 | D33: =C33*2 -> 36.56 | E33: см2
B34: Iвп | C34: 2411.48 | D34: =C34*2 -> 4822.96 | E34: см4
B35: Анп | C35: 8.43 | D35: =C35*2 -> 16.86 | E35: см2
B36: Iнп | C36: 766.65 | D36: =C36*2 -> 1533.3 | E36: см4
B37: hф | D37: 162.5 | E37: см
B38: hнп | D38: 12.5 | E38: см
B40: yф | D40: =(D33*D37+D35*D38)/(D33+D35) -> 115.15818 | E40: см
B41: iф | D41: =D34+D36+D33*(D37-D40)^2+D35*(D40-D38)^2 -> 265978.8 | E41: см4

Sheet Z
A2: =Сводная!A6 -> Z140x1,5 | B2: =INDEX(B11:B48,MATCH($A$2,$A$11:$A$48)) -> 140 | C2: =INDEX(C11:C48,MATCH($A$2,$A$11:$A$48)) -> 59.5 | D2: =INDEX(D11:D48,MATCH($A$2,$A$11:$A$48)) -> 65.5 | E2: =INDEX(E11:E48,MATCH($A$2,$A$11:$A$48)) -> 20 | F2: =INDEX(F11:F48,MATCH($A$2,$A$11:$A$48)) -> Z140 | G2: =INDEX(G11:G48,MATCH($A$2,$A$11:$A$48)) -> 140/59,5/65,5/20 | H2: =INDEX(H11:H48,MATCH($A$2,$A$11:$A$48)) -> 1.5 | I2: =INDEX(I11:I48,MATCH($A$2,$A$11:$A$48)) -> 4.37 | ... X2: =INDEX(X11:X48,MATCH($A$2,$A$11:$A$48)) -> 406.5397
A6: Наименование | B6: Стенка H | C6: Полка B1 | D6: Полка B2 | E6: Отгибы С | F6: Сечение профиля | H6: Толщина металла t, мм | I6: Геометрические характеристики полного поперечного сечения | T6: Масса 1 м.п. | U6: Теор. Ширина заготовки, мм | V6: момент инерции при свободном кручении для одиночного профиля | W6: момент инерции при свободном кручении для сдвоенного профиля | X6: Момент инерции Jy сдвоенного сечения (SCAD-Tonus) | Z6: Внутр. круг | AA6: Внешн. круг | AB6: Стенка H | AC6: Полка B1 | AD6: Полка B2 | AE6: Отгибы C | AF6: Периметр профиля, см | AG6: Приведённая толщина, мм
F7: Тип | G7: Н/В1/В2/С, мм | I7: Площадь сечения | J7: Момент инерции | K7: Момент сопр-я | L7: Момент инерции | M7: Момент сопр-я | N7: радиус инерции | P7: Положение центра тяжести
I9: Fp, | J9: Jx, | K9: Wx, | L9: Jy, | M9: Wy, | N9: rx, | O9: ry, | P9: x0, | Q9: x1, | R9: y0, | S9: y1,
I10: см2 | J10: см4 | K10: см3 | L10: см4 | M10: см3 | N10: см | O10: см | P10: см | Q10: см | R10: см | S10: см
A11: =CONCATENATE(F11,"x",(IF(H11=INT(H11),CONCATENATE(H11,",",0),H11))) -> Z140x1,0 | B11: =LEFT(G11,3) -> 140 | C11: =VALUE(MID(G11,(SEARCH("/",G11,1)+1),(SEARCH("/",G11,(SEARCH("/",G11,1)+1))-SEARCH("/",G11,1)-1))) -> 59.5 | D11: =VALUE(MID(G11,(SEARCH("/",G11,(SEARCH("/",G11,1)+1))+1),(SEARCH("/",G11,SEARCH("/",G11,(SEARCH("/",G11,1)+1))+1))-(SEARCH("/",G11,(SEARCH("/",G11,1)+1))+1))) -> 65.5 | E11: =VALUE(MID(G11,(SEARCH("/",G11,SEARCH("/",G11,(SEARCH("/",G11,1)+1))+1)+1),4)) -> 20 | F11: =CONCATENATE("Z",LEFT(G11,3)) -> Z140 | G11: 140/59,5/65,5/20 | H11: 1 | I11: 2.94 | J11: 91.97 | K11: 12.87 | L11: 28.83 | M11: 4.55 | N11: 5.6 | O11: 3.13 | P11: 6.33 | Q11: 6.07 | R11: 6.86 | S11: 7.14 | T11: 2.38 | Z11: =2*PI()*4 -> 25.132741 | AA11: =2*PI()*(4+H11) -> 31.415927 | AB11: =B11-2*(4+$H11) -> 130 | AC11: =C11-2*(4+$H11) -> 49.5 | AD11: =D11-2*(4+$H11) -> 55.5 | AE11: =E11-(4+$H11) -> 15 | AF11: =(Z11+AA11+2*(AB11+AC11+AD11+2*AE11))/10 -> 58.654867 | AG11: =I11/AF11*10 -> 0.50123718
A12: =CONCATENATE(F12,"x",(IF(H12=INT(H12),CONCATENATE(H12,",",0),H12))) -> Z140x1,2 | B12: =LEFT(G12,3) -> 140 | C12: =VALUE(MID(G12,(SEARCH("/",G12,1)+1),(SEARCH("/",G12,(SEARCH("/",G12,1)+1))-SEARCH("/",G12,1)-1))) -> 59.5 | D12: =VALUE(MID(G12,(SEARCH("/",G12,(SEARCH("/",G12,1)+1))+1),(SEARCH("/",G12,SEARCH("/",G12,(SEARCH("/",G12,1)+1))+1))-(SEARCH("/",G12,(SEARCH("/",G12,1)+1))+1))) -> 65.5 | E12: =VALUE(MID(G12,(SEARCH("/",G12,SEARCH("/",G12,(SEARCH("/",G12,1)+1))+1)+1),4)) -> 20 | F12: =CONCATENATE("Z",LEFT(G12,3)) -> Z140 | G12: 140/59,5/65,5/20 | H12: 1.2 | I12: 3.51 | J12: 109.61 | K12: 15.34 | L12: 34.18 | M12: 5.41 | N12: 5.59 | O12: 3.12 | P12: 6.32 | Q12: 6.06 | R12: 6.86 | S12: 7.14 | T12: 2.83 | Z12: =2*PI()*4 -> 25.132741 | AA12: =2*PI()*(4+H12) -> 32.672564 | AB12: =B12-2*(4+$H12) -> 129.6 | AC12: =C12-2*(4+$H12) -> 49.1 | AD12: =D12-2*(4+$H12) -> 55.1 | AE12: =E12-(4+$H12) -> 14.8 | AF12: =(Z12+AA12+2*(AB12+AC12+AD12+2*AE12))/10 -> 58.46053 | AG12: =I12/AF12*10 -> 0.60040509
A13: =CONCATENATE(F13,"x",(IF(H13=INT(H13),CONCATENATE(H13,",",0),H13))) -> Z140x1,5 | B13: =LEFT(G13,3) -> 140 | C13: =VALUE(MID(G13,(SEARCH("/",G13,1)+1),(SEARCH("/",G13,(SEARCH("/",G13,1)+1))-SEARCH("/",G13,1)-1))) -> 59.5 | D13: =VALUE(MID(G13,(SEARCH("/",G13,(SEARCH("/",G13,1)+1))+1),(SEARCH("/",G13,SEARCH("/",G13,(SEARCH("/",G13,1)+1))+1))-(SEARCH("/",G13,(SEARCH("/",G13,1)+1))+1))) -> 65.5 | E13: =VALUE(MID(G13,(SEARCH("/",G13,SEARCH("/",G13,(SEARCH("/",G13,1)+1))+1)+1),4)) -> 20 | F13: =CONCATENATE("Z",LEFT(G13,3)) -> Z140 | G13: 140/59,5/65,5/20 | H13: 1.5 | I13: 4.37 | J13: 135.6 | K13: 18.98 | L13: 41.96 | M13: 6.49 | N13: 5.57 | O13: 3.1 | P13: 6.31 | Q13: 6.04 | R13: 6.86 | S13: 7.14 | T13: 3.42 | V13: 0.0327 | W13: 0.0654 | X13: 406.5397 | Z13: =2*PI()*4 -> 25.132741 | AA13: =2*PI()*(4+H13) -> 34.557519 | AB13: =B13-2*(4+$H13) -> 129 | AC13: =C13-2*(4+$H13) -> 48.5 | AD13: =D13-2*(4+$H13) -> 54.5 | AE13: =E13-(4+$H13) -> 14.5 | AF13: =(Z13+AA13+2*(AB13+AC13+AD13+2*AE13))/10 -> 58.169026 | AG13: =I13/AF13*10 -> 0.75125893
A14: =CONCATENATE(F14,"x",(IF(H14=INT(H14),CONCATENATE(H14,",",0),H14))) -> Z140x2,0 | B14: =LEFT(G14,3) -> 140 | C14: =VALUE(MID(G14,(SEARCH("/",G14,1)+1),(SEARCH("/",G14,(SEARCH("/",G14,1)+1))-SEARCH("/",G14,1)-1))) -> 59.5 | D14: =VALUE(MID(G14,(SEARCH("/",G14,(SEARCH("/",G14,1)+1))+1),(SEARCH("/",G14,SEARCH("/",G14,(SEARCH("/",G14,1)+1))+1))-(SEARCH("/",G14,(SEARCH("/",G14,1)+1))+1))) -> 65.5 | E14: =VALUE(MID(G14,(SEARCH("/",G14,SEARCH("/",G14,(SEARCH("/",G14,1)+1))+1)+1),4)) -> 20.5 | F14: =CONCATENATE("Z",LEFT(G14,3)) -> Z140 | G14: 140/59,5/65,5/20,5 | H14: 2 | I14: 5.79 | J14: 178.2 | K14: 24.94 | L14: 55 | M14: 8.48 | N14: 5.54 | O14: 3.08 | P14: 6.28 | Q14: 6.02 | R14: 6.86 | S14: 7.14 | T14: 4.54 | V14: 0.0771 | W14: 0.1542 | X14: 534.4921 | Z14: =2*PI()*4 -> 25.132741 | AA14: =2*PI()*(4+H14) -> 37.699112 | AB14: =B14-2*(4+$H14) -> 128 | AC14: =C14-2*(4+$H14) -> 47.5 | AD14: =D14-2*(4+$H14) -> 53.5 | AE14: =E14-(4+$H14) -> 14.5 | AF14: =(Z14+AA14+2*(AB14+AC14+AD14+2*AE14))/10 -> 57.883185 | AG14: =I14/AF14*10 -> 1.0002905
A15: =CONCATENATE(F15,"x",(IF(H15=INT(H15),CONCATENATE(H15,",",0),H15))) -> Z140x2,5 | B15: =LEFT(G15,3) -> 140 | C15: =VALUE(MID(G15,(SEARCH("/",G15,1)+1),(SEARCH("/",G15,(SEARCH("/",G15,1)+1))-SEARCH("/",G15,1)-1))) -> 59.5 | D15: =VALUE(MID(G15,(SEARCH("/",G15,(SEARCH("/",G15,1)+1))+1),(SEARCH("/",G15,SEARCH("/",G15,(SEARCH("/",G15,1)+1))+1))-(SEARCH("/",G15,(SEARCH("/",G15,1)+1))+1))) -> 65.5 | E15: =VALUE(MID(G15,(SEARCH("/",G15,SEARCH("/",G15,(SEARCH("/",G15,1)+1))+1)+1),4)) -> 21 | F15: =CONCATENATE("Z",LEFT(G15,3)) -> Z140 | G15: 140/59,5/65,5/21 | H15: 2.5 | I15: 7.2 | J15: 219.52 | K15: 30.73 | L15: 67.59 | M15: 10.38 | N15: 5.52 | O15: 3.06 | P15: 6.26 | Q15: 5.99 | R15: 6.86 | S15: 7.14 | T15: 5.65 | V15: 0.1498 | W15: 0.2996 | X15: 658.7509 | Z15: =2*PI()*4 -> 25.132741 | AA15: =2*PI()*(4+H15) -> 40.840704 | AB15: =B15-2*(4+$H15) -> 127 | AC15: =C15-2*(4+$H15) -> 46.5 | AD15: =D15-2*(4+$H15) -> 52.5 | AE15: =E15-(4+$H15) -> 14.5 | AF15: =(Z15+AA15+2*(AB15+AC15+AD15+2*AE15))/10 -> 57.597345 | AG15: =I15/AF15*10 -> 1.2500576
A16: =CONCATENATE(F16,"x",(IF(H16=INT(H16),CONCATENATE(H16,",",0),H16))) -> Z140x3,0 | B16: =LEFT(G16,3) -> 140 | C16: =VALUE(MID(G16,(SEARCH("/",G16,1)+1),(SEARCH("/",G16,(SEARCH("/",G16,1)+1))-SEARCH("/",G16,1)-1))) -> 59.5 | D16: =VALUE(MID(G16,(SEARCH("/",G16,(SEARCH("/",G16,1)+1))+1),(SEARCH("/",G16,SEARCH("/",G16,(SEARCH("/",G16,1)+1))+1))-(SEARCH("/",G16,(SEARCH("/",G16,1)+1))+1))) -> 65.5 | E16: =VALUE(MID(G16,(SEARCH("/",G16,SEARCH("/",G16,(SEARCH("/",G16,1)+1))+1)+1),4)) -> 22 | F16: =CONCATENATE("Z",LEFT(G16,3)) -> Z140 | G16: 140/59,5/65,5/22 | H16: 3 | I16: 8.63 | J16: 260.29 | K16: 36.44 | L16: 80.79 | M16: 12.36 | N16: 5.49 | O16: 3.06 | P16: 6.23 | Q16: 5.97 | R16: 6.86 | S16: 7.14 | T16: 6.77 | V16: 0.2584 | W16: 0.5169 | X16: 783.7617 | Z16: =2*PI()*4 -> 25.132741 | AA16: =2*PI()*(4+H16) -> 43.982297 | AB16: =B16-2*(4+$H16) -> 126 | AC16: =C16-2*(4+$H16) -> 45.5 | AD16: =D16-2*(4+$H16) -> 51.5 | AE16: =E16-(4+$H16) -> 15 | AF16: =(Z16+AA16+2*(AB16+AC16+AD16+2*AE16))/10 -> 57.511504 | AG16: =I16/AF16*10 -> 1.5005694
A17: =CONCATENATE(F17,"x",(IF(H17=INT(H17),CONCATENATE(H17,",",0),H17))) -> Z160x1,0 | B17: =LEFT(G17,3) -> 160 | C17: =VALUE(MID(G17,(SEARCH("/",G17,1)+1),(SEARCH("/",G17,(SEARCH("/",G17,1)+1))-SEARCH("/",G17,1)-1))) -> 59.5 | D17: =VALUE(MID(G17,(SEARCH("/",G17,(SEARCH("/",G17,1)+1))+1),(SEARCH("/",G17,SEARCH("/",G17,(SEARCH("/",G17,1)+1))+1))-(SEARCH("/",G17,(SEARCH("/",G17,1)+1))+1))) -> 65.5 | E17: =VALUE(MID(G17,(SEARCH("/",G17,SEARCH("/",G17,(SEARCH("/",G17,1)+1))+1)+1),4)) -> 20 | F17: =CONCATENATE("Z",LEFT(G17,3)) -> Z160 | G17: 160/59,5/65,5/20 | H17: 1 | I17: 3.14 | J17: 125.29 | K17: 15.36 | L17: 28.83 | M17: 4.55 | N17: 6.32 | O17: 3.03 | P17: 6.34 | Q17: 6.06 | R17: 7.85 | S17: 8.15 | T17: 2.54 | Z17: =2*PI()*4 -> 25.132741 | AA17: =2*PI()*(4+H17) -> 31.415927 | AB17: =B17-2*(4+$H17) -> 150 | AC17: =C17-2*(4+$H17) -> 49.5 | AD17: =D17-2*(4+$H17) -> 55.5 | AE17: =E17-(4+$H17) -> 15 | AF17: =(Z17+AA17+2*(AB17+AC17+AD17+2*AE17))/10 -> 62.654867 | AG17: =I17/AF17*10 -> 0.5011582
A18: =CONCATENATE(F18,"x",(IF(H18=INT(H18),CONCATENATE(H18,",",0),H18))) -> Z160x1,2 | B18: =LEFT(G18,3) -> 160 | C18: =VALUE(MID(G18,(SEARCH("/",G18,1)+1),(SEARCH("/",G18,(SEARCH("/",G18,1)+1))-SEARCH("/",G18,1)-1))) -> 59.5 | D18: =VALUE(MID(G18,(SEARCH("/",G18,(SEARCH("/",G18,1)+1))+1),(SEARCH("/",G18,SEARCH("/",G18,(SEARCH("/",G18,1)+1))+1))-(SEARCH("/",G18,(SEARCH("/",G18,1)+1))+1))) -> 65.5 | E18: =VALUE(MID(G18,(SEARCH("/",G18,SEARCH("/",G18,(SEARCH("/",G18,1)+1))+1)+1),4)) -> 20 | F18: =CONCATENATE("Z",LEFT(G18,3)) -> Z160 | G18: 160/59,5/65,5/20 | H18: 1.2 | I18: 3.75 | J18: 149.39 | K18: 18.32 | L18: 34.19 | M18: 5.4 | N18: 6.31 | O18: 3.02 | P18: 6.33 | Q18: 6.05 | R18: 7.85 | S18: 8.15 | T18: 3.02 | Z18: =2*PI()*4 -> 25.132741 | AA18: =2*PI()*(4+H18) -> 32.672564 | AB18: =B18-2*(4+$H18) -> 149.6 | AC18: =C18-2*(4+$H18) -> 49.1 | AD18: =D18-2*(4+$H18) -> 55.1 | AE18: =E18-(4+$H18) -> 14.8 | AF18: =(Z18+AA18+2*(AB18+AC18+AD18+2*AE18))/10 -> 62.46053 | AG18: =I18/AF18*10 -> 0.60037915
A19: =CONCATENATE(F19,"x",(IF(H19=INT(H19),CONCATENATE(H19,",",0),H19))) -> Z160x1,5 | B19: =LEFT(G19,3) -> 160 | C19: =VALUE(MID(G19,(SEARCH("/",G19,1)+1),(SEARCH("/",G19,(SEARCH("/",G19,1)+1))-SEARCH("/",G19,1)-1))) -> 59.5 | D19: =VALUE(MID(G19,(SEARCH("/",G19,(SEARCH("/",G19,1)+1))+1),(SEARCH("/",G19,SEARCH("/",G19,(SEARCH("/",G19,1)+1))+1))-(SEARCH("/",G19,(SEARCH("/",G19,1)+1))+1))) -> 65.5 | E19: =VALUE(MID(G19,(SEARCH("/",G19,SEARCH("/",G19,(SEARCH("/",G19,1)+1))+1)+1),4)) -> 20 | F19: =CONCATENATE("Z",LEFT(G19,3)) -> Z160 | G19: 160/59,5/65,5/20 | H19: 1.5 | I19: 4.67 | J19: 184.96 | K19: 22.68 | L19: 41.97 | M19: 6.48 | N19: 6.29 | O19: 3 | P19: 6.32 | Q19: 6.03 | R19: 7.85 | S19: 8.15 | T19: 3.66 | V19: 0.0349 | W19: 0.0699 | X19: 427.6042 | Z19: =2*PI()*4 -> 25.132741 | AA19: =2*PI()*(4+H19) -> 34.557519 | AB19: =B19-2*(4+$H19) -> 149 | AC19: =C19-2*(4+$H19) -> 48.5 | AD19: =D19-2*(4+$H19) -> 54.5 | AE19: =E19-(4+$H19) -> 14.5 | AF19: =(Z19+AA19+2*(AB19+AC19+AD19+2*AE19))/10 -> 62.169026 | AG19: =I19/AF19*10 -> 0.75117793
A20: =CONCATENATE(F20,"x",(IF(H20=INT(H20),CONCATENATE(H20,",",0),H20))) -> Z160x2,0 | B20: =LEFT(G20,3) -> 160 | C20: =VALUE(MID(G20,(SEARCH("/",G20,1)+1),(SEARCH("/",G20,(SEARCH("/",G20,1)+1))-SEARCH("/",G20,1)-1))) -> 59.5 | D20: =VALUE(MID(G20,(SEARCH("/",G20,(SEARCH("/",G20,1)+1))+1),(SEARCH("/",G20,SEARCH("/",G20,(SEARCH("/",G20,1)+1))+1))-(SEARCH("/",G20,(SEARCH("/",G20,1)+1))+1))) -> 65.5 | E20: =VALUE(MID(G20,(SEARCH("/",G20,SEARCH("/",G20,(SEARCH("/",G20,1)+1))+1)+1),4)) -> 20.5 | F20: =CONCATENATE("Z",LEFT(G20,3)) -> Z160 | G20: 160/59,5/65,5/20,5 | H20: 2 | I20: 6.19 | J20: 243.39 | K20: 29.85 | L20: 55.01 | M20: 8.47 | N20: 6.27 | O20: 2.98 | P20: 6.29 | Q20: 6.01 | R20: 7.85 | S20: 8.15 | T20: 4.86 | V20: 0.0824 | W20: 0.1648 | X20: 562.3428 | Z20: =2*PI()*4 -> 25.132741 | AA20: =2*PI()*(4+H20) -> 37.699112 | AB20: =B20-2*(4+$H20) -> 148 | AC20: =C20-2*(4+$H20) -> 47.5 | AD20: =D20-2*(4+$H20) -> 53.5 | AE20: =E20-(4+$H20) -> 14.5 | AF20: =(Z20+AA20+2*(AB20+AC20+AD20+2*AE20))/10 -> 61.883185 | AG20: =I20/AF20*10 -> 1.0002717
A21: =CONCATENATE(F21,"x",(IF(H21=INT(H21),CONCATENATE(H21,",",0),H21))) -> Z160x2,5 | B21: =LEFT(G21,3) -> 160 | C21: =VALUE(MID(G21,(SEARCH("/",G21,1)+1),(SEARCH("/",G21,(SEARCH("/",G21,1)+1))-SEARCH("/",G21,1)-1))) -> 59.5 | D21: =VALUE(MID(G21,(SEARCH("/",G21,(SEARCH("/",G21,1)+1))+1),(SEARCH("/",G21,SEARCH("/",G21,(SEARCH("/",G21,1)+1))+1))-(SEARCH("/",G21,(SEARCH("/",G21,1)+1))+1))) -> 65.5 | E21: =VALUE(MID(G21,(SEARCH("/",G21,SEARCH("/",G21,(SEARCH("/",G21,1)+1))+1)+1),4)) -> 21 | F21: =CONCATENATE("Z",LEFT(G21,3)) -> Z160 | G21: 160/59,5/65,5/21 | H21: 2.5 | I21: 7.7 | J21: 300.24 | K21: 36.82 | L21: 67.6 | M21: 10.36 | N21: 6.24 | O21: 2.96 | P21: 6.27 | Q21: 5.98 | R21: 7.85 | S21: 8.15 | T21: 6.04 | V21: 0.1602 | W21: 0.3204 | X21: 693.2717 | Z21: =2*PI()*4 -> 25.132741 | AA21: =2*PI()*(4+H21) -> 40.840704 | AB21: =B21-2*(4+$H21) -> 147 | AC21: =C21-2*(4+$H21) -> 46.5 | AD21: =D21-2*(4+$H21) -> 52.5 | AE21: =E21-(4+$H21) -> 14.5 | AF21: =(Z21+AA21+2*(AB21+AC21+AD21+2*AE21))/10 -> 61.597345 | AG21: =I21/AF21*10 -> 1.2500539
A22: =CONCATENATE(F22,"x",(IF(H22=INT(H22),CONCATENATE(H22,",",0),H22))) -> Z160x3,0 | B22: =LEFT(G22,3) -> 160 | C22: =VALUE(MID(G22,(SEARCH("/",G22,1)+1),(SEARCH("/",G22,(SEARCH("/",G22,1)+1))-SEARCH("/",G22,1)-1))) -> 59.5 | D22: =VALUE(MID(G22,(SEARCH("/",G22,(SEARCH("/",G22,1)+1))+1),(SEARCH("/",G22,SEARCH("/",G22,(SEARCH("/",G22,1)+1))+1))-(SEARCH("/",G22,(SEARCH("/",G22,1)+1))+1))) -> 65.5 | E22: =VALUE(MID(G22,(SEARCH("/",G22,SEARCH("/",G22,(SEARCH("/",G22,1)+1))+1)+1),4)) -> 22 | F22: =CONCATENATE("Z",LEFT(G22,3)) -> Z160 | G22: 160/59,5/65,5/22 | H22: 3 | I22: 9.23 | J22: 356.55 | K22: 43.73 | L22: 80.81 | M22: 12.34 | N22: 6.21 | O22: 2.95 | P22: 6.24 | Q22: 5.96 | R22: 7.85 | S22: 8.15 | T22: 7.24 | V22: 0.2764 | W22: 0.5529 | X22: 824.8377 | Z22: =2*PI()*4 -> 25.132741 | AA22: =2*PI()*(4+H22) -> 43.982297 | AB22: =B22-2*(4+$H22) -> 146 | AC22: =C22-2*(4+$H22) -> 45.5 | AD22: =D22-2*(4+$H22) -> 51.5 | AE22: =E22-(4+$H22) -> 15 | AF22: =(Z22+AA22+2*(AB22+AC22+AD22+2*AE22))/10 -> 61.511504 | AG22: =I22/AF22*10 -> 1.5005323
A23: =CONCATENATE(F23,"x",(IF(H23=INT(H23),CONCATENATE(H23,",",0),H23))) -> Z200x1,0 | B23: =LEFT(G23,3) -> 200 | C23: =VALUE(MID(G23,(SEARCH("/",G23,1)+1),(SEARCH("/",G23,(SEARCH("/",G23,1)+1))-SEARCH("/",G23,1)-1))) -> 59.5 | D23: =VALUE(MID(G23,(SEARCH("/",G23,(SEARCH("/",G23,1)+1))+1),(SEARCH("/",G23,SEARCH("/",G23,(SEARCH("/",G23,1)+1))+1))-(SEARCH("/",G23,(SEARCH("/",G23,1)+1))+1))) -> 65.5 | E23: =VALUE(MID(G23,(SEARCH("/",G23,SEARCH("/",G23,(SEARCH("/",G23,1)+1))+1)+1),4)) -> 20 | F23: =CONCATENATE("Z",LEFT(G23,3)) -> Z200 | G23: 200/59,5/65,5/20 | H23: 1 | I23: 3.54 | J23: 211.12 | K23: 20.76 | L23: 28.84 | M23: 4.54 | N23: 7.73 | O23: 2.85 | P23: 6.36 | Q23: 6.04 | R23: 9.84 | S23: 10.16 | T23: 2.87 | Z23: =2*PI()*4 -> 25.132741 | AA23: =2*PI()*(4+H23) -> 31.415927 | AB23: =B23-2*(4+$H23) -> 190 | AC23: =C23-2*(4+$H23) -> 49.5 | AD23: =D23-2*(4+$H23) -> 55.5 | AE23: =E23-(4+$H23) -> 15 | AF23: =(Z23+AA23+2*(AB23+AC23+AD23+2*AE23))/10 -> 70.654867 | AG23: =I23/AF23*10 -> 0.50102706
A24: =CONCATENATE(F24,"x",(IF(H24=INT(H24),CONCATENATE(H24,",",0),H24))) -> Z200x1,2 | B24: =LEFT(G24,3) -> 200 | C24: =VALUE(MID(G24,(SEARCH("/",G24,1)+1),(SEARCH("/",G24,(SEARCH("/",G24,1)+1))-SEARCH("/",G24,1)-1))) -> 59.5 | D24: =VALUE(MID(G24,(SEARCH("/",G24,(SEARCH("/",G24,1)+1))+1),(SEARCH("/",G24,SEARCH("/",G24,(SEARCH("/",G24,1)+1))+1))-(SEARCH("/",G24,(SEARCH("/",G24,1)+1))+1))) -> 65.5 | E24: =VALUE(MID(G24,(SEARCH("/",G24,SEARCH("/",G24,(SEARCH("/",G24,1)+1))+1)+1),4)) -> 20 | F24: =CONCATENATE("Z",LEFT(G24,3)) -> Z200 | G24: 200/59,5/65,5/20 | H24: 1.2 | I24: 4.23 | J24: 251.92 | K24: 24.77 | L24: 34.2 | M24: 5.39 | N24: 7.71 | O24: 2.84 | P24: 6.35 | Q24: 6.03 | R24: 9.84 | S24: 10.16 | T24: 3.41 | Z24: =2*PI()*4 -> 25.132741 | AA24: =2*PI()*(4+H24) -> 32.672564 | AB24: =B24-2*(4+$H24) -> 189.6 | AC24: =C24-2*(4+$H24) -> 49.1 | AD24: =D24-2*(4+$H24) -> 55.1 | AE24: =E24-(4+$H24) -> 14.8 | AF24: =(Z24+AA24+2*(AB24+AC24+AD24+2*AE24))/10 -> 70.46053 | AG24: =I24/AF24*10 -> 0.6003361
A25: =CONCATENATE(F25,"x",(IF(H25=INT(H25),CONCATENATE(H25,",",0),H25))) -> Z200x1,5 | B25: =LEFT(G25,3) -> 200 | C25: =VALUE(MID(G25,(SEARCH("/",G25,1)+1),(SEARCH("/",G25,(SEARCH("/",G25,1)+1))-SEARCH("/",G25,1)-1))) -> 59.5 | D25: =VALUE(MID(G25,(SEARCH("/",G25,(SEARCH("/",G25,1)+1))+1),(SEARCH("/",G25,SEARCH("/",G25,(SEARCH("/",G25,1)+1))+1))-(SEARCH("/",G25,(SEARCH("/",G25,1)+1))+1))) -> 65.5 | E25: =VALUE(MID(G25,(SEARCH("/",G25,SEARCH("/",G25,(SEARCH("/",G25,1)+1))+1)+1),4)) -> 20 | F25: =CONCATENATE("Z",LEFT(G25,3)) -> Z200 | G25: 200/59,5/65,5/20 | H25: 1.5 | I25: 5.27 | J25: 312.23 | K25: 30.7 | L25: 41.98 | M25: 6.47 | N25: 7.7 | O25: 2.82 | P25: 6.34 | Q25: 6.01 | R25: 9.84 | S25: 10.16 | T25: 4.13 | V25: 0.0394 | W25: 0.0789 | X25: 469.7332 | Z25: =2*PI()*4 -> 25.132741 | AA25: =2*PI()*(4+H25) -> 34.557519 | AB25: =B25-2*(4+$H25) -> 189 | AC25: =C25-2*(4+$H25) -> 48.5 | AD25: =D25-2*(4+$H25) -> 54.5 | AE25: =E25-(4+$H25) -> 14.5 | AF25: =(Z25+AA25+2*(AB25+AC25+AD25+2*AE25))/10 -> 70.169026 | AG25: =I25/AF25*10 -> 0.75104363
A26: =CONCATENATE(F26,"x",(IF(H26=INT(H26),CONCATENATE(H26,",",0),H26))) -> Z200x2,0 | B26: =LEFT(G26,3) -> 200 | C26: =VALUE(MID(G26,(SEARCH("/",G26,1)+1),(SEARCH("/",G26,(SEARCH("/",G26,1)+1))-SEARCH("/",G26,1)-1))) -> 59.5 | D26: =VALUE(MID(G26,(SEARCH("/",G26,(SEARCH("/",G26,1)+1))+1),(SEARCH("/",G26,SEARCH("/",G26,(SEARCH("/",G26,1)+1))+1))-(SEARCH("/",G26,(SEARCH("/",G26,1)+1))+1))) -> 65.5 | E26: =VALUE(MID(G26,(SEARCH("/",G26,SEARCH("/",G26,(SEARCH("/",G26,1)+1))+1)+1),4)) -> 20.5 | F26: =CONCATENATE("Z",LEFT(G26,3)) -> Z200 | G26: 200/59,5/65,5/20,5 | H26: 2 | I26: 6.99 | J26: 411.68 | K26: 40.48 | L26: 55.03 | M26: 8.45 | N26: 7.67 | O26: 2.8 | P26: 6.31 | Q26: 5.99 | R26: 9.84 | S26: 10.16 | T26: 5.49 | V26: 0.0931 | W26: 0.1862 | X26: 618.0441 | Z26: =2*PI()*4 -> 25.132741 | AA26: =2*PI()*(4+H26) -> 37.699112 | AB26: =B26-2*(4+$H26) -> 188 | AC26: =C26-2*(4+$H26) -> 47.5 | AD26: =D26-2*(4+$H26) -> 53.5 | AE26: =E26-(4+$H26) -> 14.5 | AF26: =(Z26+AA26+2*(AB26+AC26+AD26+2*AE26))/10 -> 69.883185 | AG26: =I26/AF26*10 -> 1.0002406
A27: =CONCATENATE(F27,"x",(IF(H27=INT(H27),CONCATENATE(H27,",",0),H27))) -> Z200x2,5 | B27: =LEFT(G27,3) -> 200 | C27: =VALUE(MID(G27,(SEARCH("/",G27,1)+1),(SEARCH("/",G27,(SEARCH("/",G27,1)+1))-SEARCH("/",G27,1)-1))) -> 59.5 | D27: =VALUE(MID(G27,(SEARCH("/",G27,(SEARCH("/",G27,1)+1))+1),(SEARCH("/",G27,SEARCH("/",G27,(SEARCH("/",G27,1)+1))+1))-(SEARCH("/",G27,(SEARCH("/",G27,1)+1))+1))) -> 65.5 | E27: =VALUE(MID(G27,(SEARCH("/",G27,SEARCH("/",G27,(SEARCH("/",G27,1)+1))+1)+1),4)) -> 21 | F27: =CONCATENATE("Z",LEFT(G27,3)) -> Z200 | G27: 200/59,5/65,5/21 | H27: 2.5 | I27: 8.7 | J27: 508.87 | K27: 50.03 | L27: 67.63 | M27: 10.34 | N27: 7.64 | O27: 2.78 | P27: 6.29 | Q27: 5.96 | R27: 9.83 | S27: 10.17 | T27: 6.83 | V27: 0.181 | W27: 0.3621 | X27: 762.3134 | Z27: =2*PI()*4 -> 25.132741 | AA27: =2*PI()*(4+H27) -> 40.840704 | AB27: =B27-2*(4+$H27) -> 187 | AC27: =C27-2*(4+$H27) -> 46.5 | AD27: =D27-2*(4+$H27) -> 52.5 | AE27: =E27-(4+$H27) -> 14.5 | AF27: =(Z27+AA27+2*(AB27+AC27+AD27+2*AE27))/10 -> 69.597345 | AG27: =I27/AF27*10 -> 1.2500477
A28: =CONCATENATE(F28,"x",(IF(H28=INT(H28),CONCATENATE(H28,",",0),H28))) -> Z200x3,0 | B28: =LEFT(G28,3) -> 200 | C28: =VALUE(MID(G28,(SEARCH("/",G28,1)+1),(SEARCH("/",G28,(SEARCH("/",G28,1)+1))-SEARCH("/",G28,1)-1))) -> 59.5 | D28: =VALUE(MID(G28,(SEARCH("/",G28,(SEARCH("/",G28,1)+1))+1),(SEARCH("/",G28,SEARCH("/",G28,(SEARCH("/",G28,1)+1))+1))-(SEARCH("/",G28,(SEARCH("/",G28,1)+1))+1))) -> 65.5 | E28: =VALUE(MID(G28,(SEARCH("/",G28,SEARCH("/",G28,(SEARCH("/",G28,1)+1))+1)+1),4)) -> 22 | F28: =CONCATENATE("Z",LEFT(G28,3)) -> Z200 | G28: 200/59,5/65,5/22 | H28: 3 | I28: 10.43 | J28: 605.64 | K28: 59.55 | L28: 80.84 | M28: 12.31 | N28: 7.62 | O28: 2.78 | P28: 6.26 | Q28: 5.94 | R28: 9.83 | S28: 10.17 | T28: 8.18 | V28: 0.3124 | W28: 0.6249 | X28: 906.9897 | Z28: =2*PI()*4 -> 25.132741 | AA28: =2*PI()*(4+H28) -> 43.982297 | AB28: =B28-2*(4+$H28) -> 186 | AC28: =C28-2*(4+$H28) -> 45.5 | AD28: =D28-2*(4+$H28) -> 51.5 | AE28: =E28-(4+$H28) -> 15 | AF28: =(Z28+AA28+2*(AB28+AC28+AD28+2*AE28))/10 -> 69.511504 | AG28: =I28/AF28*10 -> 1.5004711
A29: =CONCATENATE(F29,"x",(IF(H29=INT(H29),CONCATENATE(H29,",",0),H29))) -> Z200x3,5 | B29: =LEFT(G29,3) -> 200 | C29: =VALUE(MID(G29,(SEARCH("/",G29,1)+1),(SEARCH("/",G29,(SEARCH("/",G29,1)+1))-SEARCH("/",G29,1)-1))) -> 59.5 | D29: =VALUE(MID(G29,(SEARCH("/",G29,(SEARCH("/",G29,1)+1))+1),(SEARCH("/",G29,SEARCH("/",G29,(SEARCH("/",G29,1)+1))+1))-(SEARCH("/",G29,(SEARCH("/",G29,1)+1))+1))) -> 65.5 | E29: =VALUE(MID(G29,(SEARCH("/",G29,SEARCH("/",G29,(SEARCH("/",G29,1)+1))+1)+1),4)) -> 23 | F29: =CONCATENATE("Z",LEFT(G29,3)) -> Z200 | G29: 200/59,5/65,5/23 | H29: 3.5 | I29: 12.15 | J29: 700.71 | K29: 68.9 | L29: 93.93 | M29: 14.25 | N29: 7.59 | O29: 2.78 | P29: 6.24 | Q29: 5.91 | R29: 9.84 | S29: 10.16 | T29: 9.54 | Z29: =2*PI()*4 -> 25.132741 | AA29: =2*PI()*(4+H29) -> 47.12389 | AB29: =B29-2*(4+$H29) -> 185 | AC29: =C29-2*(4+$H29) -> 44.5 | AD29: =D29-2*(4+$H29) -> 50.5 | AE29: =E29-(4+$H29) -> 15.5 | AF29: =(Z29+AA29+2*(AB29+AC29+AD29+2*AE29))/10 -> 69.425663 | AG29: =I29/AF29*10 -> 1.7500733
A30: =CONCATENATE(F30,"x",(IF(H30=INT(H30),CONCATENATE(H30,",",0),H30))) -> Z250x1,0 | B30: =LEFT(G30,3) -> 250 | C30: =VALUE(MID(G30,(SEARCH("/",G30,1)+1),(SEARCH("/",G30,(SEARCH("/",G30,1)+1))-SEARCH("/",G30,1)-1))) -> 67 | D30: =VALUE(MID(G30,(SEARCH("/",G30,(SEARCH("/",G30,1)+1))+1),(SEARCH("/",G30,SEARCH("/",G30,(SEARCH("/",G30,1)+1))+1))-(SEARCH("/",G30,(SEARCH("/",G30,1)+1))+1))) -> 78 | E30: =VALUE(MID(G30,(SEARCH("/",G30,SEARCH("/",G30,(SEARCH("/",G30,1)+1))+1)+1),4)) -> 21.5 | F30: =CONCATENATE("Z",LEFT(G30,3)) -> Z250 | G30: 250/67/78/21,5 | H30: 1 | I30: 4.27 | J30: 392.49 | K30: 30.61 | L30: 44.14 | M30: 5.88 | N30: 9.59 | O30: 3.21 | P30: 7.51 | Q30: 6.89 | R30: 12.18 | S30: 12.82 | T30: 3.46 | Z30: =2*PI()*4 -> 25.132741 | AA30: =2*PI()*(4+H30) -> 31.415927 | AB30: =B30-2*(4+$H30) -> 240 | AC30: =C30-2*(4+$H30) -> 57 | AD30: =D30-2*(4+$H30) -> 68 | AE30: =E30-(4+$H30) -> 16.5 | AF30: =(Z30+AA30+2*(AB30+AC30+AD30+2*AE30))/10 -> 85.254867 | AG30: =I30/AF30*10 -> 0.50085117
A31: =CONCATENATE(F31,"x",(IF(H31=INT(H31),CONCATENATE(H31,",",0),H31))) -> Z250x1,2 | B31: =LEFT(G31,3) -> 250 | C31: =VALUE(MID(G31,(SEARCH("/",G31,1)+1),(SEARCH("/",G31,(SEARCH("/",G31,1)+1))-SEARCH("/",G31,1)-1))) -> 67 | D31: =VALUE(MID(G31,(SEARCH("/",G31,(SEARCH("/",G31,1)+1))+1),(SEARCH("/",G31,SEARCH("/",G31,(SEARCH("/",G31,1)+1))+1))-(SEARCH("/",G31,(SEARCH("/",G31,1)+1))+1))) -> 78 | E31: =VALUE(MID(G31,(SEARCH("/",G31,SEARCH("/",G31,(SEARCH("/",G31,1)+1))+1)+1),4)) -> 21.5 | F31: =CONCATENATE("Z",LEFT(G31,3)) -> Z250 | G31: 250/67/78/21,5 | H31: 1.2 | I31: 5.11 | J31: 468.78 | K31: 36.56 | L31: 52.42 | M31: 6.99 | N31: 9.58 | O31: 3.2 | P31: 7.5 | Q31: 6.88 | R31: 12.18 | S31: 12.82 | T31: 4.12 | Z31: =2*PI()*4 -> 25.132741 | AA31: =2*PI()*(4+H31) -> 32.672564 | AB31: =B31-2*(4+$H31) -> 239.6 | AC31: =C31-2*(4+$H31) -> 56.6 | AD31: =D31-2*(4+$H31) -> 67.6 | AE31: =E31-(4+$H31) -> 16.3 | AF31: =(Z31+AA31+2*(AB31+AC31+AD31+2*AE31))/10 -> 85.06053 | AG31: =I31/AF31*10 -> 0.60074866
A32: =CONCATENATE(F32,"x",(IF(H32=INT(H32),CONCATENATE(H32,",",0),H32))) -> Z250x1,5 | B32: =LEFT(G32,3) -> 250 | C32: =VALUE(MID(G32,(SEARCH("/",G32,1)+1),(SEARCH("/",G32,(SEARCH("/",G32,1)+1))-SEARCH("/",G32,1)-1))) -> 67 | D32: =VALUE(MID(G32,(SEARCH("/",G32,(SEARCH("/",G32,1)+1))+1),(SEARCH("/",G32,SEARCH("/",G32,(SEARCH("/",G32,1)+1))+1))-(SEARCH("/",G32,(SEARCH("/",G32,1)+1))+1))) -> 78 | E32: =VALUE(MID(G32,(SEARCH("/",G32,SEARCH("/",G32,(SEARCH("/",G32,1)+1))+1)+1),4)) -> 21.5 | F32: =CONCATENATE("Z",LEFT(G32,3)) -> Z250 | G32: 250/67/78/21,5 | H32: 1.5 | I32: 6.36 | J32: 581.84 | K32: 45.37 | L32: 64.5 | M32: 8.44 | N32: 9.56 | O32: 3.18 | P32: 7.49 | Q32: 6.86 | R32: 12.18 | S32: 12.82 | T32: 4.99 | V32: 0.0476 | W32: 0.0953 | X32: 734.9701 | Z32: =2*PI()*4 -> 25.132741 | AA32: =2*PI()*(4+H32) -> 34.557519 | AB32: =B32-2*(4+$H32) -> 239 | AC32: =C32-2*(4+$H32) -> 56 | AD32: =D32-2*(4+$H32) -> 67 | AE32: =E32-(4+$H32) -> 16 | AF32: =(Z32+AA32+2*(AB32+AC32+AD32+2*AE32))/10 -> 84.769026 | AG32: =I32/AF32*10 -> 0.75027404
A33: =CONCATENATE(F33,"x",(IF(H33=INT(H33),CONCATENATE(H33,",",0),H33))) -> Z250x2,0 | B33: =LEFT(G33,3) -> 250 | C33: =VALUE(MID(G33,(SEARCH("/",G33,1)+1),(SEARCH("/",G33,(SEARCH("/",G33,1)+1))-SEARCH("/",G33,1)-1))) -> 67 | D33: =VALUE(MID(G33,(SEARCH("/",G33,(SEARCH("/",G33,1)+1))+1),(SEARCH("/",G33,SEARCH("/",G33,(SEARCH("/",G33,1)+1))+1))-(SEARCH("/",G33,(SEARCH("/",G33,1)+1))+1))) -> 78 | E33: =VALUE(MID(G33,(SEARCH("/",G33,SEARCH("/",G33,(SEARCH("/",G33,1)+1))+1)+1),4)) -> 21.5 | F33: =CONCATENATE("Z",LEFT(G33,3)) -> Z250 | G33: 250/67/78/21,5 | H33: 2 | I33: 8.43 | J33: 766.65 | K33: 59.78 | L33: 83.77 | M33: 10.92 | N33: 9.53 | O33: 3.15 | P33: 7.46 | Q33: 6.84 | R33: 12.18 | S33: 12.82 | T33: 6.62 | V33: 0.1123 | W33: 0.2246 | X33: 964.766 | Z33: =2*PI()*4 -> 25.132741 | AA33: =2*PI()*(4+H33) -> 37.699112 | AB33: =B33-2*(4+$H33) -> 238 | AC33: =C33-2*(4+$H33) -> 55 | AD33: =D33-2*(4+$H33) -> 66 | AE33: =E33-(4+$H33) -> 15.5 | AF33: =(Z33+AA33+2*(AB33+AC33+AD33+2*AE33))/10 -> 84.283185 | AG33: =I33/AF33*10 -> 1.0001995
A34: =CONCATENATE(F34,"x",(IF(H34=INT(H34),CONCATENATE(H34,",",0),H34))) -> Z250x2,5 | B34: =LEFT(G34,3) -> 250 | C34: =VALUE(MID(G34,(SEARCH("/",G34,1)+1),(SEARCH("/",G34,(SEARCH("/",G34,1)+1))-SEARCH("/",G34,1)-1))) -> 68 | D34: =VALUE(MID(G34,(SEARCH("/",G34,(SEARCH("/",G34,1)+1))+1),(SEARCH("/",G34,SEARCH("/",G34,(SEARCH("/",G34,1)+1))+1))-(SEARCH("/",G34,(SEARCH("/",G34,1)+1))+1))) -> 79 | E34: =VALUE(MID(G34,(SEARCH("/",G34,SEARCH("/",G34,(SEARCH("/",G34,1)+1))+1)+1),4)) -> 22 | F34: =CONCATENATE("Z",LEFT(G34,3)) -> Z250 | G34: 250/68/79/22 | H34: 2.5 | I34: 10.55 | J34: 957.29 | K34: 74.65 | L34: 106.98 | M34: 13.73 | N34: 9.52 | O34: 3.18 | P34: 7.54 | Q34: 6.91 | R34: 12.18 | S34: 12.82 | T34: 8.28 | V34: 0.2196 | W34: 0.4392 | X34: 1234.036 | Z34: =2*PI()*4 -> 25.132741 | AA34: =2*PI()*(4+H34) -> 40.840704 | AB34: =B34-2*(4+$H34) -> 237 | AC34: =C34-2*(4+$H34) -> 55 | AD34: =D34-2*(4+$H34) -> 66 | AE34: =E34-(4+$H34) -> 15.5 | AF34: =(Z34+AA34+2*(AB34+AC34+AD34+2*AE34))/10 -> 84.397345 | AG34: =I34/AF34*10 -> 1.2500393
A35: =CONCATENATE(F35,"x",(IF(H35=INT(H35),CONCATENATE(H35,",",0),H35))) -> Z250x3,0 | B35: =LEFT(G35,3) -> 250 | C35: =VALUE(MID(G35,(SEARCH("/",G35,1)+1),(SEARCH("/",G35,(SEARCH("/",G35,1)+1))-SEARCH("/",G35,1)-1))) -> 69 | D35: =VALUE(MID(G35,(SEARCH("/",G35,(SEARCH("/",G35,1)+1))+1),(SEARCH("/",G35,SEARCH("/",G35,(SEARCH("/",G35,1)+1))+1))-(SEARCH("/",G35,(SEARCH("/",G35,1)+1))+1))) -> 80 | E35: =VALUE(MID(G35,(SEARCH("/",G35,SEARCH("/",G35,(SEARCH("/",G35,1)+1))+1)+1),4)) -> 22.5 | F35: =CONCATENATE("Z",LEFT(G35,3)) -> Z250 | G35: 250/69/80/22,5 | H35: 3 | I35: 12.68 | J35: 1147.5 | K35: 89.49 | L35: 131.16 | M35: 16.57 | N35: 9.51 | O35: 3.21 | P35: 7.61 | Q35: 6.99 | R35: 12.18 | S35: 12.82 | T35: 9.95 | V35: 0.3799 | W35: 0.7599 | X35: 1514.9835 | Z35: =2*PI()*4 -> 25.132741 | AA35: =2*PI()*(4+H35) -> 43.982297 | AB35: =B35-2*(4+$H35) -> 236 | AC35: =C35-2*(4+$H35) -> 55 | AD35: =D35-2*(4+$H35) -> 66 | AE35: =E35-(4+$H35) -> 15.5 | AF35: =(Z35+AA35+2*(AB35+AC35+AD35+2*AE35))/10 -> 84.511504 | AG35: =I35/AF35*10 -> 1.5003875
A36: =CONCATENATE(F36,"x",(IF(H36=INT(H36),CONCATENATE(H36,",",0),H36))) -> Z300x2,0 | B36: =LEFT(G36,3) -> 300 | C36: =VALUE(MID(G36,(SEARCH("/",G36,1)+1),(SEARCH("/",G36,(SEARCH("/",G36,1)+1))-SEARCH("/",G36,1)-1))) -> 85 | D36: =VALUE(MID(G36,(SEARCH("/",G36,(SEARCH("/",G36,1)+1))+1),(SEARCH("/",G36,SEARCH("/",G36,(SEARCH("/",G36,1)+1))+1))-(SEARCH("/",G36,(SEARCH("/",G36,1)+1))+1))) -> 93 | E36: =VALUE(MID(G36,(SEARCH("/",G36,SEARCH("/",G36,(SEARCH("/",G36,1)+1))+1)+1),4)) -> 29.5 | F36: =CONCATENATE("Z",LEFT(G36,3)) -> Z300 | G36: 300/85/93/29,5 | H36: 2 | I36: 10.41 | J36: 1382.43 | K36: 90.77 | L36: 167.92 | M36: 18.2 | N36: 11.52 | O36: 4.01 | P36: 9.02 | Q36: 8.58 | R36: 14.78 | S36: 15.22 | T36: 8.17 | V36: 0.1387 | W36: 0.2774 | X36: 1882.4297 | Z36: =2*PI()*4 -> 25.132741 | AA36: =2*PI()*(4+H36) -> 37.699112 | AB36: =B36-2*(4+$H36) -> 288 | AC36: =C36-2*(4+$H36) -> 73 | AD36: =D36-2*(4+$H36) -> 81 | AE36: =E36-(4+$H36) -> 23.5 | AF36: =(Z36+AA36+2*(AB36+AC36+AD36+2*AE36))/10 -> 104.08319 | AG36: =I36/AF36*10 -> 1.0001616
A37: =CONCATENATE(F37,"x",(IF(H37=INT(H37),CONCATENATE(H37,",",0),H37))) -> Z300x2,5 | B37: =LEFT(G37,3) -> 300 | C37: =VALUE(MID(G37,(SEARCH("/",G37,1)+1),(SEARCH("/",G37,(SEARCH("/",G37,1)+1))-SEARCH("/",G37,1)-1))) -> 86 | D37: =VALUE(MID(G37,(SEARCH("/",G37,(SEARCH("/",G37,1)+1))+1),(SEARCH("/",G37,SEARCH("/",G37,(SEARCH("/",G37,1)+1))+1))-(SEARCH("/",G37,(SEARCH("/",G37,1)+1))+1))) -> 94 | E37: =VALUE(MID(G37,(SEARCH("/",G37,SEARCH("/",G37,(SEARCH("/",G37,1)+1))+1)+1),4)) -> 30 | F37: =CONCATENATE("Z",LEFT(G37,3)) -> Z300 | G37: 300/86/94/30 | H37: 2.5 | I37: 13.03 | J37: 1726.2 | K37: 113.35 | L37: 213.52 | M37: 22.84 | N37: 11.51 | O37: 4.04 | P37: 9.09 | Q37: 8.66 | R37: 14.78 | S37: 15.22 | T37: 10.22 | V37: 0.2712 | W37: 0.5423 | X37: 2396.4253 | Z37: =2*PI()*4 -> 25.132741 | AA37: =2*PI()*(4+H37) -> 40.840704 | AB37: =B37-2*(4+$H37) -> 287 | AC37: =C37-2*(4+$H37) -> 73 | AD37: =D37-2*(4+$H37) -> 81 | AE37: =E37-(4+$H37) -> 23.5 | AF37: =(Z37+AA37+2*(AB37+AC37+AD37+2*AE37))/10 -> 104.19734 | AG37: =I37/AF37*10 -> 1.2505117
A38: =CONCATENATE(F38,"x",(IF(H38=INT(H38),CONCATENATE(H38,",",0),H38))) -> Z300x3,0 | B38: =LEFT(G38,3) -> 300 | C38: =VALUE(MID(G38,(SEARCH("/",G38,1)+1),(SEARCH("/",G38,(SEARCH("/",G38,1)+1))-SEARCH("/",G38,1)-1))) -> 87 | D38: =VALUE(MID(G38,(SEARCH("/",G38,(SEARCH("/",G38,1)+1))+1),(SEARCH("/",G38,SEARCH("/",G38,(SEARCH("/",G38,1)+1))+1))-(SEARCH("/",G38,(SEARCH("/",G38,1)+1))+1))) -> 95 | E38: =VALUE(MID(G38,(SEARCH("/",G38,SEARCH("/",G38,(SEARCH("/",G38,1)+1))+1)+1),4)) -> 30.5 | F38: =CONCATENATE("Z",LEFT(G38,3)) -> Z300 | G38: 300/87/95/30,5 | H38: 3 | I38: 15.65 | J38: 2069.22 | K38: 135.88 | L38: 260.62 | M38: 27.51 | N38: 11.49 | O38: 4.08 | P38: 9.17 | Q38: 8.73 | R38: 14.78 | S38: 15.22 | T38: 12.28 | V38: 0.469 | W38: 0.9381 | X38: 2928.325 | Z38: =2*PI()*4 -> 25.132741 | AA38: =2*PI()*(4+H38) -> 43.982297 | AB38: =B38-2*(4+$H38) -> 286 | AC38: =C38-2*(4+$H38) -> 73 | AD38: =D38-2*(4+$H38) -> 81 | AE38: =E38-(4+$H38) -> 23.5 | AF38: =(Z38+AA38+2*(AB38+AC38+AD38+2*AE38))/10 -> 104.3115 | AG38: =I38/AF38*10 -> 1.5003139
A39: =CONCATENATE(F39,"x",(IF(H39=INT(H39),CONCATENATE(H39,",",0),H39))) -> Z300x3,5 | B39: =LEFT(G39,3) -> 300 | C39: =VALUE(MID(G39,(SEARCH("/",G39,1)+1),(SEARCH("/",G39,(SEARCH("/",G39,1)+1))-SEARCH("/",G39,1)-1))) -> 88 | D39: =VALUE(MID(G39,(SEARCH("/",G39,(SEARCH("/",G39,1)+1))+1),(SEARCH("/",G39,SEARCH("/",G39,(SEARCH("/",G39,1)+1))+1))-(SEARCH("/",G39,(SEARCH("/",G39,1)+1))+1))) -> 96 | E39: =VALUE(MID(G39,(SEARCH("/",G39,SEARCH("/",G39,(SEARCH("/",G39,1)+1))+1)+1),4)) -> 31 | F39: =CONCATENATE("Z",LEFT(G39,3)) -> Z300 | G39: 300/88/96/31 | H39: 3.5 | I39: 18.28 | J39: 2411.48 | K39: 158.36 | L39: 309.25 | M39: 32.22 | N39: 11.48 | O39: 4.11 | P39: 9.24 | Q39: 8.81 | R39: 14.78 | S39: 15.22 | T39: 14.35 | V39: 0.7456 | W39: 1.4912 | X39: 3478.4051 | Z39: =2*PI()*4 -> 25.132741 | AA39: =2*PI()*(4+H39) -> 47.12389 | AB39: =B39-2*(4+$H39) -> 285 | AC39: =C39-2*(4+$H39) -> 73 | AD39: =D39-2*(4+$H39) -> 81 | AE39: =E39-(4+$H39) -> 23.5 | AF39: =(Z39+AA39+2*(AB39+AC39+AD39+2*AE39))/10 -> 104.42566 | AG39: =I39/AF39*10 -> 1.7505275
A40: =CONCATENATE(F40,"x",(IF(H40=INT(H40),CONCATENATE(H40,",",0),H40))) -> Z350x2,0 | B40: =LEFT(G40,3) -> 350 | C40: =VALUE(MID(G40,(SEARCH("/",G40,1)+1),(SEARCH("/",G40,(SEARCH("/",G40,1)+1))-SEARCH("/",G40,1)-1))) -> 85 | D40: =VALUE(MID(G40,(SEARCH("/",G40,(SEARCH("/",G40,1)+1))+1),(SEARCH("/",G40,SEARCH("/",G40,(SEARCH("/",G40,1)+1))+1))-(SEARCH("/",G40,(SEARCH("/",G40,1)+1))+1))) -> 93 | E40: =VALUE(MID(G40,(SEARCH("/",G40,SEARCH("/",G40,(SEARCH("/",G40,1)+1))+1)+1),4)) -> 29.5 | F40: =CONCATENATE("Z",LEFT(G40,3)) -> Z350 | G40: 350/85/93/29,5 | H40: 2 | I40: 11.41 | J40: 1994.66 | K40: 112.41 | L40: 167.95 | M40: 18.17 | N40: 13.22 | O40: 3.83 | P40: 9.04 | Q40: 8.56 | R40: 17.26 | S40: 17.74 | T40: 8.96 | V40: 0.152 | W40: 0.304 | X40: 2025.2414 | Z40: =2*PI()*4 -> 25.132741 | AA40: =2*PI()*(4+H40) -> 37.699112 | AB40: =B40-2*(4+$H40) -> 338 | AC40: =C40-2*(4+$H40) -> 73 | AD40: =D40-2*(4+$H40) -> 81 | AE40: =E40-(4+$H40) -> 23.5 | AF40: =(Z40+AA40+2*(AB40+AC40+AD40+2*AE40))/10 -> 114.08319 | AG40: =I40/AF40*10 -> 1.0001474
A41: =CONCATENATE(F41,"x",(IF(H41=INT(H41),CONCATENATE(H41,",",0),H41))) -> Z350x2,5 | B41: =LEFT(G41,3) -> 350 | C41: =VALUE(MID(G41,(SEARCH("/",G41,1)+1),(SEARCH("/",G41,(SEARCH("/",G41,1)+1))-SEARCH("/",G41,1)-1))) -> 86 | D41: =VALUE(MID(G41,(SEARCH("/",G41,(SEARCH("/",G41,1)+1))+1),(SEARCH("/",G41,SEARCH("/",G41,(SEARCH("/",G41,1)+1))+1))-(SEARCH("/",G41,(SEARCH("/",G41,1)+1))+1))) -> 94 | E41: =VALUE(MID(G41,(SEARCH("/",G41,SEARCH("/",G41,(SEARCH("/",G41,1)+1))+1)+1),4)) -> 30 | F41: =CONCATENATE("Z",LEFT(G41,3)) -> Z350 | G41: 350/86/94/30 | H41: 2.5 | I41: 14.28 | J41: 2491.77 | K41: 140.43 | L41: 213.56 | M41: 22.8 | N41: 13.21 | O41: 3.86 | P41: 9.11 | Q41: 8.64 | R41: 17.26 | S41: 17.74 | T41: 11.21 | V41: 0.2972 | W41: 0.5944 | X41: 2578.1274 | Z41: =2*PI()*4 -> 25.132741 | AA41: =2*PI()*(4+H41) -> 40.840704 | AB41: =B41-2*(4+$H41) -> 337 | AC41: =C41-2*(4+$H41) -> 73 | AD41: =D41-2*(4+$H41) -> 81 | AE41: =E41-(4+$H41) -> 23.5 | AF41: =(Z41+AA41+2*(AB41+AC41+AD41+2*AE41))/10 -> 114.19734 | AG41: =I41/AF41*10 -> 1.2504669
A42: =CONCATENATE(F42,"x",(IF(H42=INT(H42),CONCATENATE(H42,",",0),H42))) -> Z350x3,0 | B42: =LEFT(G42,3) -> 350 | C42: =VALUE(MID(G42,(SEARCH("/",G42,1)+1),(SEARCH("/",G42,(SEARCH("/",G42,1)+1))-SEARCH("/",G42,1)-1))) -> 87 | D42: =VALUE(MID(G42,(SEARCH("/",G42,(SEARCH("/",G42,1)+1))+1),(SEARCH("/",G42,SEARCH("/",G42,(SEARCH("/",G42,1)+1))+1))-(SEARCH("/",G42,(SEARCH("/",G42,1)+1))+1))) -> 95 | E42: =VALUE(MID(G42,(SEARCH("/",G42,SEARCH("/",G42,(SEARCH("/",G42,1)+1))+1)+1),4)) -> 30.5 | F42: =CONCATENATE("Z",LEFT(G42,3)) -> Z350 | G42: 350/87/95/30,5 | H42: 3 | I42: 17.15 | J42: 2988.23 | K42: 168.41 | L42: 260.67 | M42: 27.47 | N42: 13.2 | O42: 3.89 | P42: 9.18 | Q42: 8.72 | R42: 17.26 | S42: 17.74 | T42: 13.46 | V42: 0.514 | W42: 1.0281 | X42: 3150.2275 | Z42: =2*PI()*4 -> 25.132741 | AA42: =2*PI()*(4+H42) -> 43.982297 | AB42: =B42-2*(4+$H42) -> 336 | AC42: =C42-2*(4+$H42) -> 73 | AD42: =D42-2*(4+$H42) -> 81 | AE42: =E42-(4+$H42) -> 23.5 | AF42: =(Z42+AA42+2*(AB42+AC42+AD42+2*AE42))/10 -> 114.3115 | AG42: =I42/AF42*10 -> 1.5002864
A43: =CONCATENATE(F43,"x",(IF(H43=INT(H43),CONCATENATE(H43,",",0),H43))) -> Z350x3,5 | B43: =LEFT(G43,3) -> 350 | C43: =VALUE(MID(G43,(SEARCH("/",G43,1)+1),(SEARCH("/",G43,(SEARCH("/",G43,1)+1))-SEARCH("/",G43,1)-1))) -> 88 | D43: =VALUE(MID(G43,(SEARCH("/",G43,(SEARCH("/",G43,1)+1))+1),(SEARCH("/",G43,SEARCH("/",G43,(SEARCH("/",G43,1)+1))+1))-(SEARCH("/",G43,(SEARCH("/",G43,1)+1))+1))) -> 96 | E43: =VALUE(MID(G43,(SEARCH("/",G43,SEARCH("/",G43,(SEARCH("/",G43,1)+1))+1)+1),4)) -> 31 | F43: =CONCATENATE("Z",LEFT(G43,3)) -> Z350 | G43: 350/88/96/31 | H43: 3.5 | I43: 20.03 | J43: 3484.03 | K43: 196.36 | L43: 309.32 | M43: 32.17 | N43: 13.19 | O43: 3.93 | P43: 9.26 | Q43: 8.79 | R43: 17.26 | S43: 17.74 | T43: 15.72 | V43: 0.8171 | W43: 1.6342 | X43: 3741.8355 | Z43: =2*PI()*4 -> 25.132741 | AA43: =2*PI()*(4+H43) -> 47.12389 | AB43: =B43-2*(4+$H43) -> 335 | AC43: =C43-2*(4+$H43) -> 73 | AD43: =D43-2*(4+$H43) -> 81 | AE43: =E43-(4+$H43) -> 23.5 | AF43: =(Z43+AA43+2*(AB43+AC43+AD43+2*AE43))/10 -> 114.42566 | AG43: =I43/AF43*10 -> 1.7504814
... A47: =CONCATENATE(F47,"x",(IF(H47=INT(H47),CONCATENATE(H47,",",0),H47))) -> Z400x3,5 | B47: =LEFT(G47,3) -> 400 | C47: =VALUE(MID(G47,(SEARCH("/",G47,1)+1),(SEARCH("/",G47,(SEARCH("/",G47,1)+1))-SEARCH("/",G47,1)-1))) -> 88 | D47: =VALUE(MID(G47,(SEARCH("/",G47,(SEARCH("/",G47,1)+1))+1),(SEARCH("/",G47,SEARCH("/",G47,(SEARCH("/",G47,1)+1))+1))-(SEARCH("/",G47,(SEARCH("/",G47,1)+1))+1))) -> 96 | E47: =VALUE(MID(G47,(SEARCH("/",G47,SEARCH("/",G47,(SEARCH("/",G47,1)+1))+1)+1),4)) -> 31 | F47: =CONCATENATE("Z",LEFT(G47,3)) -> Z400 | G47: 400/88/96/31 | H47: 3.5 | I47: 21.78 | J47: 4806.87 | K47: 237.31 | L47: 309.38 | M47: 32.14 | N47: 14.85 | O47: 3.76 | P47: 9.27 | Q47: 8.78 | R47: 19.75 | S47: 20.25 | T47: 17.09 | V47: 0.8885 | W47: 1.7771 | X47: 4005.2659 | Z47: =2*PI()*4 -> 25.132741 | AA47: =2*PI()*(4+H47) -> 47.12389 | AB47: =B47-2*(4+$H47) -> 385 | AC47: =C47-2*(4+$H47) -> 73 | AD47: =D47-2*(4+$H47) -> 81 | AE47: =E47-(4+$H47) -> 23.5 | AF47: =(Z47+AA47+2*(AB47+AC47+AD47+2*AE47))/10 -> 124.42566 | AG47: =I47/AF47*10 -> 1.7504428
A48: =CONCATENATE(F48,"x",(IF(H48=INT(H48),CONCATENATE(H48,",",0),H48))) -> Z400x4,0 | B48: =LEFT(G48,3) -> 400 | C48: =VALUE(MID(G48,(SEARCH("/",G48,1)+1),(SEARCH("/",G48,(SEARCH("/",G48,1)+1))-SEARCH("/",G48,1)-1))) -> 89 | D48: =VALUE(MID(G48,(SEARCH("/",G48,(SEARCH("/",G48,1)+1))+1),(SEARCH("/",G48,SEARCH("/",G48,(SEARCH("/",G48,1)+1))+1))-(SEARCH("/",G48,(SEARCH("/",G48,1)+1))+1))) -> 97 | E48: =VALUE(MID(G48,(SEARCH("/",G48,SEARCH("/",G48,(SEARCH("/",G48,1)+1))+1)+1),4)) -> 31.5 | F48: =CONCATENATE("Z",LEFT(G48,3)) -> Z400 | G48: 400/89/97/31,5 | H48: 4 | I48: 24.91 | J48: 5491.68 | K48: 271.13 | L48: 359.6 | M48: 36.88 | N48: 14.84 | O48: 3.79 | P48: 9.35 | Q48: 8.85 | R48: 19.75 | S48: 20.25 | T48: 19.55 | Z48: =2*PI()*4 -> 25.132741 | AA48: =2*PI()*(4+H48) -> 50.265482 | AB48: =B48-2*(4+$H48) -> 384 | AC48: =C48-2*(4+$H48) -> 73 | AD48: =D48-2*(4+$H48) -> 81 | AE48: =E48-(4+$H48) -> 23.5 | AF48: =(Z48+AA48+2*(AB48+AC48+AD48+2*AE48))/10 -> 124.53982 | AG48: =I48/AF48*10 -> 2.0001634

Sheet C
A2: =Сводная!A9 -> C250x2,5 | B2: =INDEX(B11:B52,MATCH($A$2,$A$11:$A$52)) -> 250 | C2: =INDEX(C11:C52,MATCH($A$2,$A$11:$A$52)) -> 72 | D2: =INDEX(D11:D52,MATCH($A$2,$A$11:$A$52)) -> 72 | E2: =INDEX(E11:E52,MATCH($A$2,$A$11:$A$52)) -> 22 | F2: =INDEX(F11:F52,MATCH($A$2,$A$11:$A$52)) -> C250 | G2: =INDEX(G11:G52,MATCH($A$2,$A$11:$A$52)) -> 250/72/72/22 | H2: =INDEX(H11:H52,MATCH($A$2,$A$11:$A$52)) -> 2.5 | I2: =INDEX(I11:I52,MATCH($A$2,$A$11:$A$52)) -> 10.47 | ... X2: =INDEX(X11:X52,MATCH($A$2,$A$11:$A$52)) -> 235.721
A6: Наименование | B6: Стенка H | C6: Полка B1 | D6: Полка B2 | E6: Отгибы С | F6: Сечение профиля, | H6: Толщина металла t, мм | I6: Геометрические характеристики полного поперечного сечения | T6: Масса 1 м.п. | U6: Теор. Ширина заготовки, мм | V6: момент инерции при свободном кручении Jt для одиночного профиля | W6: момент инерции при свободном кручении Jt для сдвоенного профиля через сухарь | X6: Момент инерции Jy сдвоенного сечения через сухарь (SCAD-Tonus) | Y6: момент инерции при свободном кручении Jt для сдвоенного профиля через трубу 80 | Z6: Момент инерции Jy сдвоенного сечения через трубу 80 (SCAD-Tonus) | AB6: Внутр. круг | AC6: Внешн. круг | AD6: Стенка H | AE6: Полка B1 | AF6: Полка B2 | AG6: Отгибы C | AH6: Периметр профиля, см | AI6: Приведённая толщина, мм
F7: Тип | G7: Н/В1/В2/С, мм | I7: Площадь сечения | J7: Момент инерции | K7: Момент сопро-я | L7: Момент инерции | M7: Момент сопр-я | N7: радиус инерции | P7: Положение центра тяжести
I9: Fp, | J9: Jx, | K9: Wx, | L9: Jy, | M9: Wy, | N9: rx, | O9: ry, | P9: x0, | Q9: x1, | R9: y0, | S9: y1,
I10: см2 | J10: см4 | K10: см3 | L10: см4 | M10: см3 | N10: см | O10: см | P10: см | Q10: см | R10: см | S10: см
A11: =CONCATENATE(F11,"x",(IF(H11=INT(H11),CONCATENATE(H11,",",0),H11))) -> C140x1,0 | B11: =LEFT(G11,3) -> 140 | C11: =VALUE(MID(G11,(SEARCH("/",G11,1)+1),(SEARCH("/",G11,(SEARCH("/",G11,1)+1))-SEARCH("/",G11,1)-1))) -> 68 | D11: =VALUE(MID(G11,(SEARCH("/",G11,(SEARCH("/",G11,1)+1))+1),(SEARCH("/",G11,SEARCH("/",G11,(SEARCH("/",G11,1)+1))+1))-(SEARCH("/",G11,(SEARCH("/",G11,1)+1))+1))) -> 68 | E11: =VALUE(MID(G11,(SEARCH("/",G11,SEARCH("/",G11,(SEARCH("/",G11,1)+1))+1)+1),4)) -> 15.5 | F11: =CONCATENATE("C",LEFT(G11,3)) -> C140 | G11: 140/68/68/15,5 | H11: 1 | I11: 2.95 | J11: 94.86 | K11: 13.55 | L11: 18.87 | M11: 4.07 | N11: 5.66 | O11: 2.52 | P11: 2.17 | R11: 7 | T11: 2.4 | AB11: =2*PI()*4 -> 25.132741 | AC11: =2*PI()*(4+H11) -> 31.415927 | AD11: =B11-2*(4+$H11) -> 130 | AE11: =C11-2*(4+$H11) -> 58 | AF11: =D11-2*(4+$H11) -> 58 | AG11: =E11-(4+$H11) -> 10.5 | AH11: =(AB11+AC11+2*(AD11+AE11+AF11+2*AG11))/10 -> 59.054867 | AI11: =I11/AH11*10 -> 0.49953546
A12: =CONCATENATE(F12,"x",(IF(H12=INT(H12),CONCATENATE(H12,",",0),H12))) -> C140x1,2 | B12: =LEFT(G12,3) -> 140 | C12: =VALUE(MID(G12,(SEARCH("/",G12,1)+1),(SEARCH("/",G12,(SEARCH("/",G12,1)+1))-SEARCH("/",G12,1)-1))) -> 68 | D12: =VALUE(MID(G12,(SEARCH("/",G12,(SEARCH("/",G12,1)+1))+1),(SEARCH("/",G12,SEARCH("/",G12,(SEARCH("/",G12,1)+1))+1))-(SEARCH("/",G12,(SEARCH("/",G12,1)+1))+1))) -> 68 | E12: =VALUE(MID(G12,(SEARCH("/",G12,SEARCH("/",G12,(SEARCH("/",G12,1)+1))+1)+1),4)) -> 15.5 | F12: =CONCATENATE("C",LEFT(G12,3)) -> C140 | G12: 140/68/68/15,5 | H12: 1.2 | I12: 3.53 | J12: 113.04 | K12: 16.14 | L12: 22.59 | M12: 4.87 | N12: 5.65 | O12: 2.52 | P12: 2.17 | R12: 7 | T12: 2.86 | AB12: =2*PI()*4 -> 25.132741 | AC12: =2*PI()*(4+H12) -> 32.672564 | AD12: =B12-2*(4+$H12) -> 129.6 | AE12: =C12-2*(4+$H12) -> 57.6 | AF12: =D12-2*(4+$H12) -> 57.6 | AG12: =E12-(4+$H12) -> 10.3 | AH12: =(AB12+AC12+2*(AD12+AE12+AF12+2*AG12))/10 -> 58.86053 | AI12: =I12/AH12*10 -> 0.59972276
A13: =CONCATENATE(F13,"x",(IF(H13=INT(H13),CONCATENATE(H13,",",0),H13))) -> C140x1,5 | B13: =LEFT(G13,3) -> 140 | C13: =VALUE(MID(G13,(SEARCH("/",G13,1)+1),(SEARCH("/",G13,(SEARCH("/",G13,1)+1))-SEARCH("/",G13,1)-1))) -> 68 | D13: =VALUE(MID(G13,(SEARCH("/",G13,(SEARCH("/",G13,1)+1))+1),(SEARCH("/",G13,SEARCH("/",G13,(SEARCH("/",G13,1)+1))+1))-(SEARCH("/",G13,(SEARCH("/",G13,1)+1))+1))) -> 68 | E13: =VALUE(MID(G13,(SEARCH("/",G13,SEARCH("/",G13,(SEARCH("/",G13,1)+1))+1)+1),4)) -> 15.5 | F13: =CONCATENATE("C",LEFT(G13,3)) -> C140 | G13: 140/68/68/15,5 | H13: 1.5 | I13: 4.39 | J13: 139.92 | K13: 19.98 | L13: 27.07 | M13: 5.83 | N13: 5.64 | O13: 2.48 | P13: 2.16 | R13: 7 | T13: 3.45 | V13: 0.033 | W13: 0.066 | X13: 104.999 | AB13: =2*PI()*4 -> 25.132741 | AC13: =2*PI()*(4+H13) -> 34.557519 | AD13: =B13-2*(4+$H13) -> 129 | AE13: =C13-2*(4+$H13) -> 57 | AF13: =D13-2*(4+$H13) -> 57 | AG13: =E13-(4+$H13) -> 10 | AH13: =(AB13+AC13+2*(AD13+AE13+AF13+2*AG13))/10 -> 58.569026 | AI13: =I13/AH13*10 -> 0.74954294
A14: =CONCATENATE(F14,"x",(IF(H14=INT(H14),CONCATENATE(H14,",",0),H14))) -> C140x2,0 | B14: =LEFT(G14,3) -> 140 | C14: =VALUE(MID(G14,(SEARCH("/",G14,1)+1),(SEARCH("/",G14,(SEARCH("/",G14,1)+1))-SEARCH("/",G14,1)-1))) -> 68 | D14: =VALUE(MID(G14,(SEARCH("/",G14,(SEARCH("/",G14,1)+1))+1),(SEARCH("/",G14,SEARCH("/",G14,(SEARCH("/",G14,1)+1))+1))-(SEARCH("/",G14,(SEARCH("/",G14,1)+1))+1))) -> 68 | E14: =VALUE(MID(G14,(SEARCH("/",G14,SEARCH("/",G14,(SEARCH("/",G14,1)+1))+1)+1),4)) -> 17 | F14: =CONCATENATE("C",LEFT(G14,3)) -> C140 | G14: 140/68/68/17 | H14: 2 | I14: 5.86 | J14: 185.12 | K14: 26.44 | L14: 36.33 | M14: 7.91 | N14: 5.61 | O14: 2.48 | P14: 2.21 | R14: 7 | T14: 4.61 | V14: 0.078 | W14: 0.156 | X14: 140.301 | AB14: =2*PI()*4 -> 25.132741 | AC14: =2*PI()*(4+H14) -> 37.699112 | AD14: =B14-2*(4+$H14) -> 128 | AE14: =C14-2*(4+$H14) -> 56 | AF14: =D14-2*(4+$H14) -> 56 | AG14: =E14-(4+$H14) -> 11 | AH14: =(AB14+AC14+2*(AD14+AE14+AF14+2*AG14))/10 -> 58.683185 | AI14: =I14/AH14*10 -> 0.99858247
A15: =CONCATENATE(F15,"x",(IF(H15=INT(H15),CONCATENATE(H15,",",0),H15))) -> C140x2,5 | B15: =LEFT(G15,3) -> 140 | C15: =VALUE(MID(G15,(SEARCH("/",G15,1)+1),(SEARCH("/",G15,(SEARCH("/",G15,1)+1))-SEARCH("/",G15,1)-1))) -> 68 | D15: =VALUE(MID(G15,(SEARCH("/",G15,(SEARCH("/",G15,1)+1))+1),(SEARCH("/",G15,SEARCH("/",G15,(SEARCH("/",G15,1)+1))+1))-(SEARCH("/",G15,(SEARCH("/",G15,1)+1))+1))) -> 68 | E15: =VALUE(MID(G15,(SEARCH("/",G15,SEARCH("/",G15,(SEARCH("/",G15,1)+1))+1)+1),4)) -> 18.5 | F15: =CONCATENATE("C",LEFT(G15,3)) -> C140 | G15: 140/68/68/18,5 | H15: 2.5 | I15: 7.34 | J15: 229.51 | K15: 32.78 | L15: 45.65 | M15: 10.04 | N15: 5.58 | O15: 2.49 | P15: 2.25 | R15: 7 | T15: 5.77 | V15: 0.153 | W15: 0.306 | X15: 179.184 | AB15: =2*PI()*4 -> 25.132741 | AC15: =2*PI()*(4+H15) -> 40.840704 | AD15: =B15-2*(4+$H15) -> 127 | AE15: =C15-2*(4+$H15) -> 55 | AF15: =D15-2*(4+$H15) -> 55 | AG15: =E15-(4+$H15) -> 12 | AH15: =(AB15+AC15+2*(AD15+AE15+AF15+2*AG15))/10 -> 58.797345 | AI15: =I15/AH15*10 -> 1.2483557
A16: =CONCATENATE(F16,"x",(IF(H16=INT(H16),CONCATENATE(H16,",",0),H16))) -> C140x3,0 | B16: =LEFT(G16,3) -> 140 | C16: =VALUE(MID(G16,(SEARCH("/",G16,1)+1),(SEARCH("/",G16,(SEARCH("/",G16,1)+1))-SEARCH("/",G16,1)-1))) -> 68 | D16: =VALUE(MID(G16,(SEARCH("/",G16,(SEARCH("/",G16,1)+1))+1),(SEARCH("/",G16,SEARCH("/",G16,(SEARCH("/",G16,1)+1))+1))-(SEARCH("/",G16,(SEARCH("/",G16,1)+1))+1))) -> 68 | E16: =VALUE(MID(G16,(SEARCH("/",G16,SEARCH("/",G16,(SEARCH("/",G16,1)+1))+1)+1),4)) -> 20 | F16: =CONCATENATE("C",LEFT(G16,3)) -> C140 | G16: 140/68/68/20 | H16: 3 | I16: 8.83 | J16: 273.07 | K16: 39.01 | L16: 55.03 | M16: 12.22 | N16: 5.55 | O16: 2.49 | P16: 2.3 | R16: 7 | T16: 6.94 | V16: 0.265 | W16: 0.529 | X16: 219.521 | AB16: =2*PI()*4 -> 25.132741 | AC16: =2*PI()*(4+H16) -> 43.982297 | AD16: =B16-2*(4+$H16) -> 126 | AE16: =C16-2*(4+$H16) -> 54 | AF16: =D16-2*(4+$H16) -> 54 | AG16: =E16-(4+$H16) -> 13 | AH16: =(AB16+AC16+2*(AD16+AE16+AF16+2*AG16))/10 -> 58.911504 | AI16: =I16/AH16*10 -> 1.4988584
A17: =CONCATENATE(F17,"x",(IF(H17=INT(H17),CONCATENATE(H17,",",0),H17))) -> C160x1,0 | B17: =LEFT(G17,3) -> 160 | C17: =VALUE(MID(G17,(SEARCH("/",G17,1)+1),(SEARCH("/",G17,(SEARCH("/",G17,1)+1))-SEARCH("/",G17,1)-1))) -> 68 | D17: =VALUE(MID(G17,(SEARCH("/",G17,(SEARCH("/",G17,1)+1))+1),(SEARCH("/",G17,SEARCH("/",G17,(SEARCH("/",G17,1)+1))+1))-(SEARCH("/",G17,(SEARCH("/",G17,1)+1))+1))) -> 68 | E17: =VALUE(MID(G17,(SEARCH("/",G17,SEARCH("/",G17,(SEARCH("/",G17,1)+1))+1)+1),4)) -> 15.5 | F17: =CONCATENATE("C",LEFT(G17,3)) -> C160 | G17: 160/68/68/15,5 | H17: 1 | I17: 3.15 | J17: 128.66 | K17: 16.08 | L17: 20.54 | M17: 4.31 | N17: 6.38 | O17: 2.55 | P17: 2.04 | R17: 8 | T17: 2.57 | AB17: =2*PI()*4 -> 25.132741 | AC17: =2*PI()*(4+H17) -> 31.415927 | AD17: =B17-2*(4+$H17) -> 150 | AE17: =C17-2*(4+$H17) -> 58 | AF17: =D17-2*(4+$H17) -> 58 | AG17: =E17-(4+$H17) -> 10.5 | AH17: =(AB17+AC17+2*(AD17+AE17+AF17+2*AG17))/10 -> 63.054867 | AI17: =I17/AH17*10 -> 0.49956493
A18: =CONCATENATE(F18,"x",(IF(H18=INT(H18),CONCATENATE(H18,",",0),H18))) -> C160x1,2 | B18: =LEFT(G18,3) -> 160 | C18: =VALUE(MID(G18,(SEARCH("/",G18,1)+1),(SEARCH("/",G18,(SEARCH("/",G18,1)+1))-SEARCH("/",G18,1)-1))) -> 68 | D18: =VALUE(MID(G18,(SEARCH("/",G18,(SEARCH("/",G18,1)+1))+1),(SEARCH("/",G18,SEARCH("/",G18,(SEARCH("/",G18,1)+1))+1))-(SEARCH("/",G18,(SEARCH("/",G18,1)+1))+1))) -> 68 | E18: =VALUE(MID(G18,(SEARCH("/",G18,SEARCH("/",G18,(SEARCH("/",G18,1)+1))+1)+1),4)) -> 15.5 | F18: =CONCATENATE("C",LEFT(G18,3)) -> C160 | G18: 160/68/68/15,5 | H18: 1.2 | I18: 3.77 | J18: 153.38 | K18: 19.17 | L18: 24.55 | M18: 5.15 | N18: 6.37 | O18: 2.55 | P18: 2.04 | R18: 8 | T18: 3.05 | AB18: =2*PI()*4 -> 25.132741 | AC18: =2*PI()*(4+H18) -> 32.672564 | AD18: =B18-2*(4+$H18) -> 149.6 | AE18: =C18-2*(4+$H18) -> 57.6 | AF18: =D18-2*(4+$H18) -> 57.6 | AG18: =E18-(4+$H18) -> 10.3 | AH18: =(AB18+AC18+2*(AD18+AE18+AF18+2*AG18))/10 -> 62.86053 | AI18: =I18/AH18*10 -> 0.5997404
A19: =CONCATENATE(F19,"x",(IF(H19=INT(H19),CONCATENATE(H19,",",0),H19))) -> C160x1,5 | B19: =LEFT(G19,3) -> 160 | C19: =VALUE(MID(G19,(SEARCH("/",G19,1)+1),(SEARCH("/",G19,(SEARCH("/",G19,1)+1))-SEARCH("/",G19,1)-1))) -> 68 | D19: =VALUE(MID(G19,(SEARCH("/",G19,(SEARCH("/",G19,1)+1))+1),(SEARCH("/",G19,SEARCH("/",G19,(SEARCH("/",G19,1)+1))+1))-(SEARCH("/",G19,(SEARCH("/",G19,1)+1))+1))) -> 68 | E19: =VALUE(MID(G19,(SEARCH("/",G19,SEARCH("/",G19,(SEARCH("/",G19,1)+1))+1)+1),4)) -> 15.5 | F19: =CONCATENATE("C",LEFT(G19,3)) -> C160 | G19: 160/68/68/15,5 | H19: 1.5 | I19: 4.69 | J19: 190.19 | K19: 23.77 | L19: 28.3 | M19: 5.93 | N19: 6.36 | O19: 2.45 | P19: 2.03 | R19: 8 | T19: 3.68 | V19: 0.035 | W19: 0.07 | X19: 102.952 | AB19: =2*PI()*4 -> 25.132741 | AC19: =2*PI()*(4+H19) -> 34.557519 | AD19: =B19-2*(4+$H19) -> 149 | AE19: =C19-2*(4+$H19) -> 57 | AF19: =D19-2*(4+$H19) -> 57 | AG19: =E19-(4+$H19) -> 10 | AH19: =(AB19+AC19+2*(AD19+AE19+AF19+2*AG19))/10 -> 62.569026 | AI19: =I19/AH19*10 -> 0.74957216
A20: =CONCATENATE(F20,"x",(IF(H20=INT(H20),CONCATENATE(H20,",",0),H20))) -> C160x2,0 | B20: =LEFT(G20,3) -> 160 | C20: =VALUE(MID(G20,(SEARCH("/",G20,1)+1),(SEARCH("/",G20,(SEARCH("/",G20,1)+1))-SEARCH("/",G20,1)-1))) -> 68 | D20: =VALUE(MID(G20,(SEARCH("/",G20,(SEARCH("/",G20,1)+1))+1),(SEARCH("/",G20,SEARCH("/",G20,(SEARCH("/",G20,1)+1))+1))-(SEARCH("/",G20,(SEARCH("/",G20,1)+1))+1))) -> 68 | E20: =VALUE(MID(G20,(SEARCH("/",G20,SEARCH("/",G20,(SEARCH("/",G20,1)+1))+1)+1),4)) -> 17 | F20: =CONCATENATE("C",LEFT(G20,3)) -> C160 | G20: 160/68/68/17 | H20: 2 | I20: 6.26 | J20: 252.01 | K20: 31.5 | L20: 37.99 | M20: 8.03 | N20: 6.34 | O20: 2.46 | P20: 2.07 | R20: 8 | T20: 4.92 | V20: 0.083 | W20: 0.167 | X20: 140.375 | AB20: =2*PI()*4 -> 25.132741 | AC20: =2*PI()*(4+H20) -> 37.699112 | AD20: =B20-2*(4+$H20) -> 148 | AE20: =C20-2*(4+$H20) -> 56 | AF20: =D20-2*(4+$H20) -> 56 | AG20: =E20-(4+$H20) -> 11 | AH20: =(AB20+AC20+2*(AD20+AE20+AF20+2*AG20))/10 -> 62.683185 | AI20: =I20/AH20*10 -> 0.99867292
A21: =CONCATENATE(F21,"x",(IF(H21=INT(H21),CONCATENATE(H21,",",0),H21))) -> C160x2,5 | B21: =LEFT(G21,3) -> 160 | C21: =VALUE(MID(G21,(SEARCH("/",G21,1)+1),(SEARCH("/",G21,(SEARCH("/",G21,1)+1))-SEARCH("/",G21,1)-1))) -> 68 | D21: =VALUE(MID(G21,(SEARCH("/",G21,(SEARCH("/",G21,1)+1))+1),(SEARCH("/",G21,SEARCH("/",G21,(SEARCH("/",G21,1)+1))+1))-(SEARCH("/",G21,(SEARCH("/",G21,1)+1))+1))) -> 68 | E21: =VALUE(MID(G21,(SEARCH("/",G21,SEARCH("/",G21,(SEARCH("/",G21,1)+1))+1)+1),4)) -> 18.5 | F21: =CONCATENATE("C",LEFT(G21,3)) -> C160 | G21: 160/68/68/18,5 | H21: 2.5 | I21: 7.84 | J21: 312.94 | K21: 39.11 | L21: 47.77 | M21: 10.2 | N21: 6.31 | O21: 2.46 | P21: 2.12 | R21: 8 | T21: 6.16 | V21: 0.163 | W21: 0.327 | X21: 179.295 | AB21: =2*PI()*4 -> 25.132741 | AC21: =2*PI()*(4+H21) -> 40.840704 | AD21: =B21-2*(4+$H21) -> 147 | AE21: =C21-2*(4+$H21) -> 55 | AF21: =D21-2*(4+$H21) -> 55 | AG21: =E21-(4+$H21) -> 12 | AH21: =(AB21+AC21+2*(AD21+AE21+AF21+2*AG21))/10 -> 62.797345 | AI21: =I21/AH21*10 -> 1.2484604
A22: =CONCATENATE(F22,"x",(IF(H22=INT(H22),CONCATENATE(H22,",",0),H22))) -> C160x3,0 | B22: =LEFT(G22,3) -> 160 | C22: =VALUE(MID(G22,(SEARCH("/",G22,1)+1),(SEARCH("/",G22,(SEARCH("/",G22,1)+1))-SEARCH("/",G22,1)-1))) -> 68 | D22: =VALUE(MID(G22,(SEARCH("/",G22,(SEARCH("/",G22,1)+1))+1),(SEARCH("/",G22,SEARCH("/",G22,(SEARCH("/",G22,1)+1))+1))-(SEARCH("/",G22,(SEARCH("/",G22,1)+1))+1))) -> 68 | E22: =VALUE(MID(G22,(SEARCH("/",G22,SEARCH("/",G22,(SEARCH("/",G22,1)+1))+1)+1),4)) -> 20 | F22: =CONCATENATE("C",LEFT(G22,3)) -> C160 | G22: 160/68/68/20 | H22: 3 | I22: 9.43 | J22: 372.93 | K22: 46.61 | L22: 57.62 | M22: 12.42 | N22: 6.28 | O22: 2.47 | P22: 2.16 | R22: 8 | T22: 7.41 | V22: 0.283 | W22: 0.565 | X22: 219.677 | AB22: =2*PI()*4 -> 25.132741 | AC22: =2*PI()*(4+H22) -> 43.982297 | AD22: =B22-2*(4+$H22) -> 146 | AE22: =C22-2*(4+$H22) -> 54 | AF22: =D22-2*(4+$H22) -> 54 | AG22: =E22-(4+$H22) -> 13 | AH22: =(AB22+AC22+2*(AD22+AE22+AF22+2*AG22))/10 -> 62.911504 | AI22: =I22/AH22*10 -> 1.4989309
A23: =CONCATENATE(F23,"x",(IF(H23=INT(H23),CONCATENATE(H23,",",0),H23))) -> C170x1,5 | B23: =LEFT(G23,3) -> 170 | C23: =VALUE(MID(G23,(SEARCH("/",G23,1)+1),(SEARCH("/",G23,(SEARCH("/",G23,1)+1))-SEARCH("/",G23,1)-1))) -> 68 | D23: =VALUE(MID(G23,(SEARCH("/",G23,(SEARCH("/",G23,1)+1))+1),(SEARCH("/",G23,SEARCH("/",G23,(SEARCH("/",G23,1)+1))+1))-(SEARCH("/",G23,(SEARCH("/",G23,1)+1))+1))) -> 68 | E23: =VALUE(MID(G23,(SEARCH("/",G23,SEARCH("/",G23,(SEARCH("/",G23,1)+1))+1)+1),4)) -> 15.5 | F23: =CONCATENATE("C",LEFT(G23,3)) -> C170 | G23: 170/68/68/15,5 | H23: 1.5 | I23: 4.84 | J23: 218.81 | K23: 25.74 | L23: 28.85 | M23: 5.97 | N23: 6.72 | O23: 2.44 | P23: 1.97 | R23: 8.5 | T23: 3.8 | V23: 0.036 | W23: 0.073 | X23: 102.975 | AB23: =2*PI()*4 -> 25.132741 | AC23: =2*PI()*(4+H23) -> 34.557519 | AD23: =B23-2*(4+$H23) -> 159 | AE23: =C23-2*(4+$H23) -> 57 | AF23: =D23-2*(4+$H23) -> 57 | AG23: =E23-(4+$H23) -> 10 | AH23: =(AB23+AC23+2*(AD23+AE23+AF23+2*AG23))/10 -> 64.569026 | AI23: =I23/AH23*10 -> 0.74958541
